Workbook
Name NativeTimeline_Rpt_Month: #N/A
Name NativeTimeline_Rpt_Month1: #N/A
Name NativeTimeline_Rpt_Month2: #N/A
Name NativeTimeline_Rpt_Week: #N/A
Name NativeTimeline_Rpt_Week1: #N/A
Name NativeTimeline_Rpt_Week2: #N/A
Name Slicer_Discipline: #N/A
Name Slicer_Discipline1: #N/A

Sheet Floor-wise
A1: Row Labels | B1: Total Drgs | C1: Submitted | D1: Approved
A2: STAAD ANALYSIS AND DESIGN | B2: 1 | C2: 1 | D2: 1
A3: LAYOUT AND R/F DETAILS OF FOUNDATION | B3: 1 | C3: 1 | D3: 1
A4: LAYOUT AND R/F DETAILS OF PEDESTAL AND ANCHOR BOLT | B4: 1 | C4: 1 | D4: 1
A5: LAYOUT AND R/F DETAILS OF PLINTH BEAM | B5: 1 | C5: 1 | D5: 1
A6: R/F DETAILS OF PLINTH BEAM | B6: 1 | C6: 1 | D6: 1
A7: G.A. AND R/F DETAIL OF STEEL COLUMNS | B7: 1 | C7: 1 | D7: 1
A8: CONNECTION DETAIL OF STEEL COLUMNS | B8: 1 | C8: 1 | D8: 1
A9: G.A. LAYOUT AND DETAILS OF STAIRS | B9: 1 | C9: 1 | D9: 1
A10: CONNECTION DETAILS OF STAIRS | B10: 1 | C10: 1 | D10: 1
A11: G.A. ELEVATION AND DETAILS OF GIRTS | B11: 1 | C11: 1 | D11: 1
A12: G.A. LAYOUT AND DETAILS OF FIRST FLOOR STEEL BEAMS AND SLAB @EL. 104.65 (T.O.C OF DECK SLAB) | B12: 1 | C12: 1 | D12: 1
A13: CONNECTION DETAILS OF FIRST FLOOR STEEL BEAMS AND SLAB @EL. 104.65 (T.O.C OF DECK SLAB) | B13: 1 | C13: 1 | D13: 1
... A18: Grand Total | B18: 16 | C18: 16 | D18: 16

Sheet S-Curve Wkly
BI9: Row Labels | BJ9: Submission_1 Plan | BK9: Submission_1 Actuals | BL9: Approval Plan | BM9: Approval Actuals
A10: Row Labels | B10: Submission_1 Plan | C10: Submission_1 Actuals | D10: Approval Plan | E10: Approval Actuals | AI10: Row Labels | AJ10: Submission_1 Plan | AK10: Submission_1 Actuals | AL10: Approval Plan | AM10: Approval Actuals | BI10: 45782 | BJ10: #N/A | BK10: #N/A | BL10: #N/A | BM10: #N/A
A11: 45992 | B11: 0 | C11: 0 | D11: 0 | E11: 0 | AI11: 46027 | AJ11: 0 | AL11: 0 | AM11: 0 | BI11: 45789 | BJ11: #N/A | BK11: #N/A | BL11: #N/A | BM11: #N/A
A12: 45999 | B12: 0 | C12: 0 | D12: 0 | E12: 0 | AI12: 46034 | AJ12: 0 | AL12: 0 | AM12: 0 | BI12: 45796 | BJ12: #N/A | BK12: #N/A | BL12: #N/A | BM12: #N/A
A13: 46006 | B13: 0 | C13: 0 | D13: 0 | E13: 0 | AI13: 46041 | AJ13: 0.25 | AL13: 0 | AM13: 0 | BI13: 45803 | BJ13: #N/A | BK13: #N/A | BL13: #N/A | BM13: #N/A
A14: 46013 | B14: 0 | C14: 0.0625 | D14: 0 | E14: 0 | AI14: 46048 | AJ14: 1 | AL14: 0.5 | AM14: 0 | BI14: 45810 | BJ14: #N/A | BK14: #N/A | BL14: #N/A | BM14: #N/A
A15: 46020 | B15: 0.0625 | C15: 0.0625 | D15: 0 | E15: 0.0625 | AI15: 46055 | AJ15: 1 | AL15: 1 | AM15: 0 | BI15: 45817 | BJ15: #N/A | BK15: #N/A | BL15: #N/A | BM15: #N/A
A16: 46027 | B16: 0.3125 | C16: 0.0625 | D16: 0.0625 | E16: 0.0625 | AI16: 46062 | AJ16: 1 | AL16: 1 | AM16: 0 | BI16: 45824 | BJ16: #N/A | BK16: #N/A | BL16: #N/A | BM16: #N/A
A17: 46034 | B17: 0.4375 | C17: 0.0625 | D17: 0.3125 | E17: 0.0625 | AI17: 46069 | AJ17: 1 | AL17: 1 | AM17: 0 | BI17: 45831 | BJ17: #N/A | BK17: #N/A | BL17: #N/A | BM17: #N/A
A18: 46041 | B18: 0.5625 | C18: 0.3125 | D18: 0.5 | E18: 0.0625 | AI18: 46076 | AJ18: 1 | AL18: 1 | AM18: 0 | BI18: 45838 | BJ18: #N/A | BK18: #N/A | BL18: #N/A | BM18: #N/A
A19: 46048 | B19: 0.6875 | C19: 0.3125 | D19: 0.625 | E19: 0.0625 | AI19: 46083 | AJ19: 1 | AL19: 1 | AM19: 0 | BI19: 45845 | BJ19: #N/A | BK19: #N/A | BL19: #N/A | BM19: #N/A
A20: 46055 | B20: 0.875 | C20: 0.3125 | D20: 0.75 | E20: 0.3125 | AI20: 46090 | AJ20: 1 | AL20: 1 | AM20: 0 | BI20: 45852 | BJ20: #N/A | BK20: #N/A | BL20: #N/A | BM20: #N/A
A21: 46062 | B21: 1 | C21: 0.3125 | D21: 0.9375 | E21: 0.3125 | AI21: 46097 | AJ21: 1 | AL21: 1 | AM21: 0 | BI21: 45859 | BJ21: #N/A | BK21: #N/A | BL21: #N/A | BM21: #N/A
A22: 46069 | B22: 1 | C22: 0.3125 | D22: 1 | E22: 0.3125 | AI22: 46104 | AJ22: 1 | AL22: 1 | AM22: 0 | BI22: 45866 | BJ22: #N/A | BK22: #N/A | BL22: #N/A | BM22: #N/A
... A31: 46132 | B31: 1 | C31: 1 | D31: 1 | E31: 1 | AI31: 46167 | AJ31: 1 | AL31: 1 | AM31: 1 | BI31: 45929 | BJ31: #N/A | BK31: #N/A | BL31: #N/A | BM31: #N/A
A32: 46139 | B32: 1 | C32: 1 | D32: 1 | E32: 1 | AI32: Grand Total | BI32: 45936 | BJ32: #N/A | BK32: #N/A | BL32: #N/A | BM32: #N/A
A33: Grand Total | BI33: 45943 | BJ33: #N/A | BK33: #N/A | BL33: #N/A | BM33: #N/A
BI34: 45950 | BJ34: #N/A | BK34: #N/A | BL34: #N/A | BM34: #N/A
BI35: 45957 | BJ35: #N/A | BK35: #N/A | BL35: #N/A | BM35: #N/A
BI36: 45964 | BJ36: #N/A | BK36: #N/A | BL36: #N/A | BM36: #N/A
BI37: 45971 | BJ37: #N/A | BK37: #N/A | BL37: #N/A | BM37: #N/A
BI38: 45978 | BJ38: #N/A | BK38: #N/A | BL38: #N/A | BM38: #N/A
BI39: 45985 | BJ39: #N/A | BK39: #N/A | BL39: #N/A | BM39: #N/A
BI40: 45992 | BJ40: #N/A | BK40: #N/A | BL40: #N/A | BM40: #N/A
BI41: 45999 | BJ41: #N/A | BK41: #N/A | BL41: #N/A | BM41: #N/A
BI42: 46006 | BJ42: #N/A | BK42: #N/A | BL42: #N/A | BM42: #N/A
BI43: 46013 | BJ43: #N/A | BK43: #N/A | BL43: #N/A | BM43: #N/A
BI44: 46020 | BJ44: #N/A | BK44: #N/A | BL44: #N/A | BM44: #N/A
BI45: 46027 | BJ45: #N/A | BK45: #N/A | BL45: #N/A | BM45: #N/A
... BI61: 46139 | BJ61: #N/A | BK61: #N/A | BL61: #N/A | BM61: #N/A
BI62: Grand Total | BJ62: #N/A | BK62: #N/A | BL62: #N/A | BM62: #N/A

Sheet S-Curve Monthly
A1: Row Labels | B1: Submission_1 Plan | C1: Submission_1 Actuals | D1: Approval Plan | E1: Approval Actuals | AA1: Row Labels | AB1: Submission_1 Plan | AC1: Submission_1 Actuals | AD1: Approval Plan | AE1: Approval Actuals | BA1: Row Labels | BB1: Submission_1 Plan | BC1: Submission_1 Actuals | BD1: Approval Plan | BE1: Approval Actuals
A2: 45962 | B2: 0 | C2: 0 | D2: 0 | E2: 0 | AA2: 45962 | AB2: 0 | AC2: 0 | AD2: 0 | AE2: 0 | BA2: 45689 | BB2: #N/A | BC2: #N/A | BD2: #N/A | BE2: #N/A
A3: 45992 | B3: 0.0625 | C3: 0.0625 | D3: 0 | E3: 0 | AA3: 45992 | AB3: 0 | AC3: 0 | AD3: 0 | AE3: 0 | BA3: 45717 | BB3: #N/A | BC3: #N/A | BD3: #N/A | BE3: #N/A
A4: 46023 | B4: 0.6875 | C4: 0.3125 | D4: 0.625 | E4: 0.0625 | AA4: 46023 | AB4: 1 | AC4: 0 | AD4: 0.5 | AE4: 0 | BA4: 45748 | BB4: #N/A | BC4: #N/A | BD4: #N/A | BE4: #N/A
A5: 46054 | B5: 1 | C5: 0.3125 | D5: 1 | E5: 0.3125 | AA5: 46054 | AB5: 1 | AC5: 0 | AD5: 1 | AE5: 0 | BA5: 45778 | BB5: #N/A | BC5: #N/A | BD5: #N/A | BE5: #N/A
A6: 46082 | B6: 1 | C6: 0.3125 | D6: 1 | E6: 0.3125 | AA6: 46082 | AB6: 1 | AC6: 0 | AD6: 1 | AE6: 0 | BA6: 45809 | BB6: #N/A | BC6: #N/A | BD6: #N/A | BE6: #N/A
A7: 46113 | B7: 1 | C7: 1 | D7: 1 | E7: 1 | AA7: 46113 | AB7: 1 | AC7: 0 | AD7: 1 | AE7: 0 | BA7: 45839 | BB7: #N/A | BC7: #N/A | BD7: #N/A | BE7: #N/A
A8: Grand Total | AA8: 46143 | AB8: 1 | AC8: 0 | AD8: 1 | AE8: 1 | BA8: 45870 | BB8: #N/A | BC8: #N/A | BD8: #N/A | BE8: #N/A
AA9: 46174 | AB9: 1 | AC9: 1 | AD9: 1 | AE9: 1 | BA9: 45901 | BB9: #N/A | BC9: #N/A | BD9: #N/A | BE9: #N/A
AA10: Grand Total | BA10: 45931 | BB10: #N/A | BC10: #N/A | BD10: #N/A | BE10: #N/A
BA11: 45962 | BB11: #N/A | BC11: #N/A | BD11: #N/A | BE11: #N/A
BA12: 45992 | BB12: #N/A | BC12: #N/A | BD12: #N/A | BE12: #N/A
BA13: Grand Total | BB13: #N/A | BC13: #N/A | BD13: #N/A | BE13: #N/A

Sheet DB
A1: Row Labels | B1: Count of DRG ID
A2: Architecture | B2: 4
A3: Structural | B3: 16
A4: (blank)
A5: Grand Total | B5: 20
A24: Row Labels | B24: Count of DRG ID | C24: Count of Actual Submission to Client | D24: Count of Actual Approval Date | F24: Discipline | G24: Submission Status | H24: Approval Status
A25: Architecture | B25: 4 | C25: 4 | D25: 4 | F25: =A25 -> Architecture | G25: =GETPIVOTDATA("Count of Actual Submission to Client",$A$24,"Discipline",A25)/GETPIVOTDATA("Count of DRG ID",$A$24,"Discipline",A25) -> 1 | H25: =GETPIVOTDATA("Count of Actual Approval Date",$A$24,"Discipline",A25)/GETPIVOTDATA("Count of DRG ID",$A$24,"Discipline",A25) -> 1
A26: Structural | B26: 16 | C26: 16 | D26: 16 | F26: =A26 -> Structural | G26: =GETPIVOTDATA("Count of Actual Submission to Client",$A$24,"Discipline",A26)/GETPIVOTDATA("Count of DRG ID",$A$24,"Discipline",A26) -> 1 | H26: =GETPIVOTDATA("Count of Actual Approval Date",$A$24,"Discipline",A26)/GETPIVOTDATA("Count of DRG ID",$A$24,"Discipline",A26) -> 1
A27: Grand Total | B27: 20 | C27: 20 | D27: 20 | F27: =A27 -> Grand Total | G27: =GETPIVOTDATA("Count of Actual Submission to Client",$A$24,"Discipline","Structural")/GETPIVOTDATA("Count of DRG ID",$A$24,"Discipline","Structural") -> 1 | H27: =GETPIVOTDATA("Count of Actual Approval Date",$A$24,"Discipline","Structural")/GETPIVOTDATA("Count of DRG ID",$A$24,"Discipline","Structural") -> 1
A39: Speedometer | B39: Value | C39: Pointer | D39: Value
A40: Start | B40: 0 | C40: Value | D40: =H27*100 -> 100
A41: Initial | B41: 30 | C41: Pointer | D41: 2
A42: Mid | B42: 40 | C42: End | D42: =SUM(B40:B44)-SUM(D40:D41) -> 98
A43: End | B43: 30
A44: Max | B44: 100
A69: Discipline | B69: Structural
A71: Row Labels | B71: Total DRG ID | C71: Submitted | D71: Approved
A72: Structural | B72: 16 | C72: 16 | D72: 16
A73: Grand Total | B73: 16 | C73: 16 | D73: 16

Sheet Master_Data
A1: S.no | B1: Discipline | C1: Category | D1: DRG ID | E1: Description | F1: MDL Title | G1: Responsible Person | H1: 1st Submission Plan | I1: 1st Submission Plan (Before changes in scope) | J1: Actual Submission to Client | K1: Revised Submission date (Plan) | L1: Actual Revised submission | M1: Planned Approval Date | N1: Actual Approval Date | O1: Planned Hard copy Sub.dates | P1: Actual Hard copy sub.dates | Q1: Dependency | R1: Approval Code | S1: Approval Status
A2: 1 | B2: Structural | C2: Structural | D2: CV-192-STR-ABF-STD-0001 | E2: STAAD ANALYSIS AND DESIGN | F2: STAAD ANALYSIS AND DESIGN | G2: Smita/Praful/Sonal | H2: 46022 | J2: 46017 | M2: 46028 | N2: 46024 | R2: V | S2: =VLOOKUP(R2,Mappings!$E$1:$F$6,2,FALSE) -> Void
A3: 2 | B3: Structural | C3: Structural | D3: CV-192-STR-ABF-DRW-0001 | E3: LAYOUT AND R/F DETAILS OF FOUNDATION | F3: LAYOUT AND R/F DETAILS OF FOUNDATION | G3: Smita/Praful/Sonal | H3: 46029 | J3: 46045 | M3: 46034 | N3: 46059 | R3: 2 | S3: =VLOOKUP(R3,Mappings!$E$1:$F$6,2,FALSE) -> Approved with comments
A4: 3 | B4: Structural | C4: Structural | D4: CV-192-STR-ABF-DRW-0002 | E4: LAYOUT AND R/F DETAILS OF PEDESTAL AND ANCHOR BOLT | F4: LAYOUT AND R/F DETAILS OF PEDESTAL AND ANCHOR BOLT | G4: Smita/Praful/Sonal | H4: 46029 | J4: 46045 | M4: 46034 | N4: 46059 | R4: 2 | S4: =VLOOKUP(R4,Mappings!$E$1:$F$6,2,FALSE) -> Approved with comments
A5: 4 | B5: Structural | C5: Structural | D5: CV-192-STR-ABF-DRW-0003 | E5: LAYOUT AND R/F DETAILS OF PLINTH BEAM | F5: LAYOUT AND R/F DETAILS OF PLINTH BEAM | G5: Smita/Praful/Sonal | H5: 46029 | J5: 46045 | M5: 46034 | N5: 46059 | R5: 2 | S5: =VLOOKUP(R5,Mappings!$E$1:$F$6,2,FALSE) -> Approved with comments
A6: 5 | B6: Structural | C6: Structural | D6: CV-192-STR-ABF-DRW-0004 | E6: R/F DETAILS OF PLINTH BEAM | F6: R/F DETAILS OF PLINTH BEAM | G6: Smita/Praful/Sonal | H6: 46029 | J6: 46045 | M6: 46034 | N6: 46059 | R6: 2 | S6: =VLOOKUP(R6,Mappings!$E$1:$F$6,2,FALSE) -> Approved with comments
A7: 6 | B7: Structural | C7: Structural | D7: CV-192-STR-ABF-DRW-0005 | E7: G.A. AND R/F DETAIL OF STEEL COLUMNS | F7: G.A. AND R/F DETAIL OF STEEL COLUMNS | G7: Smita/Praful/Sonal | H7: 46036 | J7: 46121 | M7: 46041 | N7: 46133 | R7: 1 | S7: =VLOOKUP(R7,Mappings!$E$1:$F$6,2,FALSE) -> Approved
A8: 7 | B8: Structural | C8: Structural | D8: CV-192-STR-ABF-DRW-0006 | E8: CONNECTION DETAIL OF STEEL COLUMNS | F8: CONNECTION DETAIL OF STEEL COLUMNS | G8: Smita/Praful/Sonal | H8: 46038 | J8: 46121 | M8: 46043 | N8: 46133 | R8: 1 | S8: =VLOOKUP(R8,Mappings!$E$1:$F$6,2,FALSE) -> Approved
A9: 8 | B9: Structural | C9: Structural | D9: CV-192-STR-ABF-DRW-0007 | E9: G.A. LAYOUT AND DETAILS OF FIRST FLOOR STEEL BEAMS AND SLAB @EL. 104.65 (T.O.C OF DECK SLAB) | F9: G.A. LAYOUT AND DETAILS OF FIRST FLOOR STEEL BEAMS AND SLAB @EL. 104.65 (T.O.C OF DECK SLAB) | G9: Smita/Praful/Sonal | H9: 46042 | J9: 46121 | M9: 46045 | N9: 46133 | R9: 1 | S9: =VLOOKUP(R9,Mappings!$E$1:$F$6,2,FALSE) -> Approved
A10: 9 | B10: Structural | C10: Structural | D10: CV-192-STR-ABF-DRW-0008 | E10: CONNECTION DETAILS OF FIRST FLOOR STEEL BEAMS AND SLAB @EL. 104.65 (T.O.C OF DECK SLAB) | F10: CONNECTION DETAILS OF FIRST FLOOR STEEL BEAMS AND SLAB @EL. 104.65 (T.O.C OF DECK SLAB) | G10: Smita/Praful/Sonal | H10: 46044 | J10: 46121 | M10: 46049 | N10: 46133 | R10: 1 | S10: =VLOOKUP(R10,Mappings!$E$1:$F$6,2,FALSE) -> Approved
A11: 10 | B11: Structural | C11: Structural | D11: CV-192-STR-ABF-DRW-0009 | E11: G.A. LAYOUT AND DETAILS OF 2nd FLOOR STEEL BEAMS AND SLAB @EL. 110.35 (T.O.C OF DECK SLAB) | F11: G.A. LAYOUT AND DETAILS OF 2nd FLOOR STEEL BEAMS AND SLAB @EL. 110.35 (T.O.C OF DECK SLAB) | G11: Smita/Praful/Sonal | H11: 46049 | J11: 46121 | M11: 46052 | N11: 46133 | R11: 1 | S11: =VLOOKUP(R11,Mappings!$E$1:$F$6,2,FALSE) -> Approved
A12: 11 | B12: Structural | C12: Structural | D12: CV-192-STR-ABF-DRW-0010 | E12: CONNECTION DETAILS OF 2nd FLOOR STEEL BEAMS AND SLAB @EL. 110.35 (T.O.C OF DECK SLAB) | F12: CONNECTION DETAILS OF 2nd FLOOR STEEL BEAMS AND SLAB @EL. 110.35 (T.O.C OF DECK SLAB) | G12: Smita/Praful/Sonal | H12: 46051 | J12: 46121 | M12: 46056 | N12: 46133 | R12: 1 | S12: =VLOOKUP(R12,Mappings!$E$1:$F$6,2,FALSE) -> Approved
A13: 12 | B13: Structural | C13: Structural | D13: CV-192-STR-ABF-DRW-0011 | E13: G.A. LAYOUT AND DETAILS OF OF ROOF STEEL BEAMS AND SLAB @EL. 116.95 & @EL 119.9 (T.O.C OF DECK SLAB) | F13: G.A. LAYOUT AND DETAILS OF OF ROOF STEEL BEAMS AND SLAB @EL. 116.95 & @EL 119.9 (T.O.C OF DECK SLAB) | G13: Smita/Praful/Sonal | H13: 46055 | J13: 46121 | M13: 46058 | N13: 46133 | R13: 1 | S13: =VLOOKUP(R13,Mappings!$E$1:$F$6,2,FALSE) -> Approved
A14: 13 | B14: Structural | C14: Structural | D14: CV-192-STR-ABF-DRW-0012 | E14: CONNECTION DETAILS OF ROOF STEEL BEAMS AND SLAB @EL. 116.95 & @EL 119.9 (T.O.C OF DECK SLAB) | F14: CONNECTION DETAILS OF ROOF STEEL BEAMS AND SLAB @EL. 116.95 & @EL 119.9 (T.O.C OF DECK SLAB) | G14: Smita/Praful/Sonal | H14: 46057 | J14: 46121 | M14: 46062 | N14: 46133 | R14: 1 | S14: =VLOOKUP(R14,Mappings!$E$1:$F$6,2,FALSE) -> Approved
... A21: 20 | B21: Architecture | C21: Architecture | D21: CV-192-ARC-ABF-DRW-0004 | E21: SECTION | F21: SECTION | G21: Aakarsh | H21: 46052 | J21: 46183 | M21: 46057 | N21: 46147 | R21: 2 | S21: =VLOOKUP(R21,Mappings!$E$1:$F$6,2,FALSE) -> Approved with comments

Sheet DRG_Status
A1: DRG ID | B1: Discipline | C1: 1st Submission Plan_wk | D1: Actual Submission to Client_wk | E1: Planned Approval_wk | F1: Actual Approval_wk | G1: 1st Submission Plan_mth | H1: Actual Submission to Client_mth | I1: Planned Approval_mth | J1: Actual Approval_mth
A2: =Master_Data!D2 -> CV-192-STR-ABF-STD-0001 | B2: =Master_Data!B2 -> Structural | C2: =IF(Master_Data!H2="","",Master_Data!H2 - WEEKDAY(Master_Data!H2,2) + 1) -> 46020 | D2: =IF(Master_Data!J2="","",Master_Data!J2 - WEEKDAY(Master_Data!J2,2) + 1) -> 46013 | E2: =IF(Master_Data!M2="","",Master_Data!M2 - WEEKDAY(Master_Data!M2,2) + 1) -> 46027 | F2: =IF(Master_Data!N2="","",Master_Data!N2 - WEEKDAY(Master_Data!N2,2) + 1) -> 46020 | G2: =EOMONTH(Master_Data!H2,-1)+1 -> 45992 | H2: =IF(Master_Data!J2="","",EOMONTH(Master_Data!J2,-1)+1) -> 45992 | I2: =IF(Master_Data!M2="","",EOMONTH(Master_Data!M2,-1)+1) -> 46023 | J2: =IF(Master_Data!N2="","",EOMONTH(Master_Data!N2,-1)+1) -> 46023
A3: =Master_Data!D3 -> CV-192-STR-ABF-DRW-0001 | B3: =Master_Data!B3 -> Structural | C3: =IF(Master_Data!H3="","",Master_Data!H3 - WEEKDAY(Master_Data!H3,2) + 1) -> 46027 | D3: =IF(Master_Data!J3="","",Master_Data!J3 - WEEKDAY(Master_Data!J3,2) + 1) -> 46041 | E3: =IF(Master_Data!M3="","",Master_Data!M3 - WEEKDAY(Master_Data!M3,2) + 1) -> 46034 | F3: =IF(Master_Data!N3="","",Master_Data!N3 - WEEKDAY(Master_Data!N3,2) + 1) -> 46055 | G3: =EOMONTH(Master_Data!H3,-1)+1 -> 46023 | H3: =IF(Master_Data!J3="","",EOMONTH(Master_Data!J3,-1)+1) -> 46023 | I3: =IF(Master_Data!M3="","",EOMONTH(Master_Data!M3,-1)+1) -> 46023 | J3: =IF(Master_Data!N3="","",EOMONTH(Master_Data!N3,-1)+1) -> 46054
A4: =Master_Data!D4 -> CV-192-STR-ABF-DRW-0002 | B4: =Master_Data!B4 -> Structural | C4: =IF(Master_Data!H4="","",Master_Data!H4 - WEEKDAY(Master_Data!H4,2) + 1) -> 46027 | D4: =IF(Master_Data!J4="","",Master_Data!J4 - WEEKDAY(Master_Data!J4,2) + 1) -> 46041 | E4: =IF(Master_Data!M4="","",Master_Data!M4 - WEEKDAY(Master_Data!M4,2) + 1) -> 46034 | F4: =IF(Master_Data!N4="","",Master_Data!N4 - WEEKDAY(Master_Data!N4,2) + 1) -> 46055 | G4: =EOMONTH(Master_Data!H4,-1)+1 -> 46023 | H4: =IF(Master_Data!J4="","",EOMONTH(Master_Data!J4,-1)+1) -> 46023 | I4: =IF(Master_Data!M4="","",EOMONTH(Master_Data!M4,-1)+1) -> 46023 | J4: =IF(Master_Data!N4="","",EOMONTH(Master_Data!N4,-1)+1) -> 46054
A5: =Master_Data!D5 -> CV-192-STR-ABF-DRW-0003 | B5: =Master_Data!B5 -> Structural | C5: =IF(Master_Data!H5="","",Master_Data!H5 - WEEKDAY(Master_Data!H5,2) + 1) -> 46027 | D5: =IF(Master_Data!J5="","",Master_Data!J5 - WEEKDAY(Master_Data!J5,2) + 1) -> 46041 | E5: =IF(Master_Data!M5="","",Master_Data!M5 - WEEKDAY(Master_Data!M5,2) + 1) -> 46034 | F5: =IF(Master_Data!N5="","",Master_Data!N5 - WEEKDAY(Master_Data!N5,2) + 1) -> 46055 | G5: =EOMONTH(Master_Data!H5,-1)+1 -> 46023 | H5: =IF(Master_Data!J5="","",EOMONTH(Master_Data!J5,-1)+1) -> 46023 | I5: =IF(Master_Data!M5="","",EOMONTH(Master_Data!M5,-1)+1) -> 46023 | J5: =IF(Master_Data!N5="","",EOMONTH(Master_Data!N5,-1)+1) -> 46054
A6: =Master_Data!D6 -> CV-192-STR-ABF-DRW-0004 | B6: =Master_Data!B6 -> Structural | C6: =IF(Master_Data!H6="","",Master_Data!H6 - WEEKDAY(Master_Data!H6,2) + 1) -> 46027 | D6: =IF(Master_Data!J6="","",Master_Data!J6 - WEEKDAY(Master_Data!J6,2) + 1) -> 46041 | E6: =IF(Master_Data!M6="","",Master_Data!M6 - WEEKDAY(Master_Data!M6,2) + 1) -> 46034 | F6: =IF(Master_Data!N6="","",Master_Data!N6 - WEEKDAY(Master_Data!N6,2) + 1) -> 46055 | G6: =EOMONTH(Master_Data!H6,-1)+1 -> 46023 | H6: =IF(Master_Data!J6="","",EOMONTH(Master_Data!J6,-1)+1) -> 46023 | I6: =IF(Master_Data!M6="","",EOMONTH(Master_Data!M6,-1)+1) -> 46023 | J6: =IF(Master_Data!N6="","",EOMONTH(Master_Data!N6,-1)+1) -> 46054
A7: =Master_Data!D7 -> CV-192-STR-ABF-DRW-0005 | B7: =Master_Data!B7 -> Structural | C7: =IF(Master_Data!H7="","",Master_Data!H7 - WEEKDAY(Master_Data!H7,2) + 1) -> 46034 | D7: =IF(Master_Data!J7="","",Master_Data!J7 - WEEKDAY(Master_Data!J7,2) + 1) -> 46118 | E7: =IF(Master_Data!M7="","",Master_Data!M7 - WEEKDAY(Master_Data!M7,2) + 1) -> 46041 | F7: =IF(Master_Data!N7="","",Master_Data!N7 - WEEKDAY(Master_Data!N7,2) + 1) -> 46132 | G7: =EOMONTH(Master_Data!H7,-1)+1 -> 46023 | H7: =IF(Master_Data!J7="","",EOMONTH(Master_Data!J7,-1)+1) -> 46113 | I7: =IF(Master_Data!M7="","",EOMONTH(Master_Data!M7,-1)+1) -> 46023 | J7: =IF(Master_Data!N7="","",EOMONTH(Master_Data!N7,-1)+1) -> 46113
A8: =Master_Data!D8 -> CV-192-STR-ABF-DRW-0006 | B8: =Master_Data!B8 -> Structural | C8: =IF(Master_Data!H8="","",Master_Data!H8 - WEEKDAY(Master_Data!H8,2) + 1) -> 46034 | D8: =IF(Master_Data!J8="","",Master_Data!J8 - WEEKDAY(Master_Data!J8,2) + 1) -> 46118 | E8: =IF(Master_Data!M8="","",Master_Data!M8 - WEEKDAY(Master_Data!M8,2) + 1) -> 46041 | F8: =IF(Master_Data!N8="","",Master_Data!N8 - WEEKDAY(Master_Data!N8,2) + 1) -> 46132 | G8: =EOMONTH(Master_Data!H8,-1)+1 -> 46023 | H8: =IF(Master_Data!J8="","",EOMONTH(Master_Data!J8,-1)+1) -> 46113 | I8: =IF(Master_Data!M8="","",EOMONTH(Master_Data!M8,-1)+1) -> 46023 | J8: =IF(Master_Data!N8="","",EOMONTH(Master_Data!N8,-1)+1) -> 46113
A9: =Master_Data!D9 -> CV-192-STR-ABF-DRW-0007 | B9: =Master_Data!B9 -> Structural | C9: =IF(Master_Data!H9="","",Master_Data!H9 - WEEKDAY(Master_Data!H9,2) + 1) -> 46041 | D9: =IF(Master_Data!J9="","",Master_Data!J9 - WEEKDAY(Master_Data!J9,2) + 1) -> 46118 | E9: =IF(Master_Data!M9="","",Master_Data!M9 - WEEKDAY(Master_Data!M9,2) + 1) -> 46041 | F9: =IF(Master_Data!N9="","",Master_Data!N9 - WEEKDAY(Master_Data!N9,2) + 1) -> 46132 | G9: =EOMONTH(Master_Data!H9,-1)+1 -> 46023 | H9: =IF(Master_Data!J9="","",EOMONTH(Master_Data!J9,-1)+1) -> 46113 | I9: =IF(Master_Data!M9="","",EOMONTH(Master_Data!M9,-1)+1) -> 46023 | J9: =IF(Master_Data!N9="","",EOMONTH(Master_Data!N9,-1)+1) -> 46113
A10: =Master_Data!D10 -> CV-192-STR-ABF-DRW-0008 | B10: =Master_Data!B10 -> Structural | C10: =IF(Master_Data!H10="","",Master_Data!H10 - WEEKDAY(Master_Data!H10,2) + 1) -> 46041 | D10: =IF(Master_Data!J10="","",Master_Data!J10 - WEEKDAY(Master_Data!J10,2) + 1) -> 46118 | E10: =IF(Master_Data!M10="","",Master_Data!M10 - WEEKDAY(Master_Data!M10,2) + 1) -> 46048 | F10: =IF(Master_Data!N10="","",Master_Data!N10 - WEEKDAY(Master_Data!N10,2) + 1) -> 46132 | G10: =EOMONTH(Master_Data!H10,-1)+1 -> 46023 | H10: =IF(Master_Data!J10="","",EOMONTH(Master_Data!J10,-1)+1) -> 46113 | I10: =IF(Master_Data!M10="","",EOMONTH(Master_Data!M10,-1)+1) -> 46023 | J10: =IF(Master_Data!N10="","",EOMONTH(Master_Data!N10,-1)+1) -> 46113
A11: =Master_Data!D11 -> CV-192-STR-ABF-DRW-0009 | B11: =Master_Data!B11 -> Structural | C11: =IF(Master_Data!H11="","",Master_Data!H11 - WEEKDAY(Master_Data!H11,2) + 1) -> 46048 | D11: =IF(Master_Data!J11="","",Master_Data!J11 - WEEKDAY(Master_Data!J11,2) + 1) -> 46118 | E11: =IF(Master_Data!M11="","",Master_Data!M11 - WEEKDAY(Master_Data!M11,2) + 1) -> 46048 | F11: =IF(Master_Data!N11="","",Master_Data!N11 - WEEKDAY(Master_Data!N11,2) + 1) -> 46132 | G11: =EOMONTH(Master_Data!H11,-1)+1 -> 46023 | H11: =IF(Master_Data!J11="","",EOMONTH(Master_Data!J11,-1)+1) -> 46113 | I11: =IF(Master_Data!M11="","",EOMONTH(Master_Data!M11,-1)+1) -> 46023 | J11: =IF(Master_Data!N11="","",EOMONTH(Master_Data!N11,-1)+1) -> 46113
A12: =Master_Data!D12 -> CV-192-STR-ABF-DRW-0010 | B12: =Master_Data!B12 -> Structural | C12: =IF(Master_Data!H12="","",Master_Data!H12 - WEEKDAY(Master_Data!H12,2) + 1) -> 46048 | D12: =IF(Master_Data!J12="","",Master_Data!J12 - WEEKDAY(Master_Data!J12,2) + 1) -> 46118 | E12: =IF(Master_Data!M12="","",Master_Data!M12 - WEEKDAY(Master_Data!M12,2) + 1) -> 46055 | F12: =IF(Master_Data!N12="","",Master_Data!N12 - WEEKDAY(Master_Data!N12,2) + 1) -> 46132 | G12: =EOMONTH(Master_Data!H12,-1)+1 -> 46023 | H12: =IF(Master_Data!J12="","",EOMONTH(Master_Data!J12,-1)+1) -> 46113 | I12: =IF(Master_Data!M12="","",EOMONTH(Master_Data!M12,-1)+1) -> 46054 | J12: =IF(Master_Data!N12="","",EOMONTH(Master_Data!N12,-1)+1) -> 46113
A13: =Master_Data!D13 -> CV-192-STR-ABF-DRW-0011 | B13: =Master_Data!B13 -> Structural | C13: =IF(Master_Data!H13="","",Master_Data!H13 - WEEKDAY(Master_Data!H13,2) + 1) -> 46055 | D13: =IF(Master_Data!J13="","",Master_Data!J13 - WEEKDAY(Master_Data!J13,2) + 1) -> 46118 | E13: =IF(Master_Data!M13="","",Master_Data!M13 - WEEKDAY(Master_Data!M13,2) + 1) -> 46055 | F13: =IF(Master_Data!N13="","",Master_Data!N13 - WEEKDAY(Master_Data!N13,2) + 1) -> 46132 | G13: =EOMONTH(Master_Data!H13,-1)+1 -> 46054 | H13: =IF(Master_Data!J13="","",EOMONTH(Master_Data!J13,-1)+1) -> 46113 | I13: =IF(Master_Data!M13="","",EOMONTH(Master_Data!M13,-1)+1) -> 46054 | J13: =IF(Master_Data!N13="","",EOMONTH(Master_Data!N13,-1)+1) -> 46113
... A21: =Master_Data!D21 -> CV-192-ARC-ABF-DRW-0004 | B21: =Master_Data!B21 -> Architecture | C21: =IF(Master_Data!H21="","",Master_Data!H21 - WEEKDAY(Master_Data!H21,2) + 1) -> 46048 | D21: =IF(Master_Data!J21="","",Master_Data!J21 - WEEKDAY(Master_Data!J21,2) + 1) -> 46181 | E21: =IF(Master_Data!M21="","",Master_Data!M21 - WEEKDAY(Master_Data!M21,2) + 1) -> 46055 | F21: =IF(Master_Data!N21="","",Master_Data!N21 - WEEKDAY(Master_Data!N21,2) + 1) -> 46146 | G21: =EOMONTH(Master_Data!H21,-1)+1 -> 46023 | H21: =IF(Master_Data!J21="","",EOMONTH(Master_Data!J21,-1)+1) -> 46174 | I21: =IF(Master_Data!M21="","",EOMONTH(Master_Data!M21,-1)+1) -> 46054 | J21: =IF(Master_Data!N21="","",EOMONTH(Master_Data!N21,-1)+1) -> 46143

Sheet Sheet3
A1: Row Labels | B1: Sum of Submission_1 Plan | C1: Sum of Submission_1 Actuals
A2: 45962 | B2: 0 | C2: 0
A3: 45992 | B3: 0.0625 | C3: 0.0625
A4: 46023 | B4: 0.6875 | C4: 0.3125
A5: 46054 | B5: 1 | C5: 0.3125
A6: 46082 | B6: 1 | C6: 0.3125
A7: 46113 | B7: 1 | C7: 1
A8: Grand Total

Sheet S_Curve_Data
B1: Column Labels | F1: Structural | G1: =HLOOKUP(F1,$B$2:$D$3,2,FALSE) -> 16 | M1: Architecture | N1: =HLOOKUP(M1,$B$2:$D$3,2,FALSE) -> 4 | T1: MEP | U1: =HLOOKUP(T1,$B$2:$D$3,2,FALSE) -> #N/A | AA1: Structural | AB1: =HLOOKUP(AA1,$B$2:$D$3,2,FALSE) -> 16 | AH1: Architecture | AI1: =HLOOKUP(AH1,$B$2:$D$3,2,FALSE) -> 4 | AO1: MEP | AP1: =HLOOKUP(AO1,$B$2:$D$3,2,FALSE) -> #N/A
B2: Architecture | C2: Structural | F2: Rpt_Week | G2: Submission_1 Plan | H2: Submission_1 Actuals | I2: Approval Plan | J2: Approval Actuals | M2: Rpt_Week | N2: Submission_1 Plan | O2: Submission_1 Actuals | P2: Approval Plan | Q2: Approval Actuals | T2: Rpt_Week | U2: Submission_1 Plan | V2: Submission_1 Actuals | W2: Approval Plan | X2: Approval Actuals | AA2: Rpt_Month | AB2: Submission_1 Plan | AC2: Submission_1 Actuals | AD2: Approval Plan | AE2: Approval Actuals | AH2: Rpt_Month | AI2: Submission_1 Plan | AJ2: Submission_1 Actuals | AK2: Approval Plan | AL2: Approval Actuals | AO2: Rpt_Month | AP2: Submission_1 Plan | AQ2: Submission_1 Actuals | AR2: Approval Plan | AS2: Approval Actuals
A3: Total DRG ID | B3: 4 | C3: 16 | F3: =Mappings!B2 -> 45663 | G3: {=IFERROR(ROWS(_xlfn._xlws.FILTER( DRG_Status!$A$2:$A$100000, (DRG_Status!$C$2:$C$100000=S_Curve_Data!F3) * (DRG_Status!$B$2:$B$100000=S_Curve_Data!$F$1) )),0)/$G$1} -> 0 | H3: {=IFERROR(ROWS(_xlfn._xlws.FILTER( DRG_Status!$A$2:$A$100000, (DRG_Status!$D$2:$D$100000=S_Curve_Data!F3) * (DRG_Status!$B$2:$B$100000=S_Curve_Data!$F$1) )),0)/$G$1} -> 0 | I3: {=IFERROR(ROWS(_xlfn._xlws.FILTER( DRG_Status!$A$2:$A$100000, (DRG_Status!$E$2:$E$100000=S_Curve_Data!F3) * (DRG_Status!$B$2:$B$100000=S_Curve_Data!$F$1) )),0)/$G$1} -> 0 | J3: {=IFERROR(ROWS(_xlfn._xlws.FILTER( DRG_Status!$A$2:$A$100000, (DRG_Status!$F$2:$F$100000=S_Curve_Data!F3) * (DRG_Status!$B$2:$B$100000=S_Curve_Data!$F$1) )),0)/$G$1} -> 0 | M3: =Mappings!B2 -> 45663 | N3: {=IFERROR(ROWS(_xlfn._xlws.FILTER( DRG_Status!$A$2:$A$100000, (DRG_Status!$C$2:$C$100000=S_Curve_Data!M3) * (DRG_Status!$B$2:$B$100000=S_Curve_Data!$M$1) )),0)/$N$1} -> 0 | O3: {=IFERROR(ROWS(_xlfn._xlws.FILTER( DRG_Status!$A$2:$A$100000, (DRG_Status!$D$2:$D$100000=S_Curve_Data!M3) * (DRG_Status!$B$2:$B$100000=S_Curve_Data!$M$1) )),0)/$N$1} -> 0 | P3: {=IFERROR(ROWS(_xlfn._xlws.FILTER( DRG_Status!$A$2:$A$100000, (DRG_Status!$E$2:$E$100000=S_Curve_Data!M3) * (DRG_Status!$B$2:$B$100000=S_Curve_Data!$M$1) )),0)/$N$1} -> 0 | Q3: {=IFERROR(ROWS(_xlfn._xlws.FILTER( DRG_Status!$A$2:$A$100000, (DRG_Status!$F$2:$F$100000=S_Curve_Data!M3) * (DRG_Status!$B$2:$B$100000=S_Curve_Data!$M$1) )),0)/$N$1} -> 0 | T3: =Mappings!B2 -> 45663 | U3: {=IFERROR(ROWS(_xlfn._xlws.FILTER( DRG_Status!$A$2:$A$100000, (DRG_Status!$C$2:$C$100000=S_Curve_Data!T3) * (DRG_Status!$B$2:$B$100000=S_Curve_Data!$T$1) )),0)/$U$1} -> #N/A | V3: {=IFERROR(ROWS(_xlfn._xlws.FILTER( DRG_Status!$A$2:$A$100000, (DRG_Status!$D$2:$D$100000=S_Curve_Data!T3) * (DRG_Status!$B$2:$B$100000=S_Curve_Data!$T$1) )),0)/$U$1} -> #N/A | W3: {=IFERROR(ROWS(_xlfn._xlws.FILTER( DRG_Status!$A$2:$A$100000, (DRG_Status!$E$2:$E$100000=S_Curve_Data!T3) * (DRG_Status!$B$2:$B$100000=S_Curve_Data!$T$1) )),0)/$U$1} -> #N/A | X3: {=IFERROR(ROWS(_xlfn._xlws.FILTER( DRG_Status!$A$2:$A$100000, (DRG_Status!$F$2:$F$100000=S_Curve_Data!T3) * (DRG_Status!$B$2:$B$100000=S_Curve_Data!$T$1) )),0)/$U$1} -> #N/A | AA3: 45658 | AB3: {=IFERROR(ROWS(_xlfn._xlws.FILTER( DRG_Status!$A$2:$A$100000, (DRG_Status!$G$2:$G$100000=S_Curve_Data!AA3) * (DRG_Status!$B$2:$B$100000=S_Curve_Data!$AA$1) )),0)/$AB$1} -> 0 | AC3: {=IFERROR(ROWS(_xlfn._xlws.FILTER( DRG_Status!$A$2:$A$100000, (DRG_Status!$H$2:$H$100000=S_Curve_Data!AA3) * (DRG_Status!$B$2:$B$100000=S_Curve_Data!$AA$1) )),0)/$AB$1} -> 0 | AD3: {=IFERROR(ROWS(_xlfn._xlws.FILTER( DRG_Status!$A$2:$A$100000, (DRG_Status!$I$2:$I$100000=S_Curve_Data!AA3) * (DRG_Status!$B$2:$B$100000=S_Curve_Data!$AA$1) )),0)/$AB$1} -> 0 | AE3: {=IFERROR(ROWS(_xlfn._xlws.FILTER( DRG_Status!$A$2:$A$100000, (DRG_Status!$J$2:$J$100000=S_Curve_Data!AA3) * (DRG_Status!$B$2:$B$100000=S_Curve_Data!$AA$1) )),0)/$AB$1} -> 0 | AH3: 45658 | AI3: {=IFERROR(ROWS(_xlfn._xlws.FILTER( DRG_Status!$A$2:$A$100000, (DRG_Status!$G$2:$G$100000=S_Curve_Data!AH3) * (DRG_Status!$B$2:$B$100000=S_Curve_Data!$AH$1) )),0)/$AI$1} -> 0 | AJ3: {=IFERROR(ROWS(_xlfn._xlws.FILTER( DRG_Status!$A$2:$A$100000, (DRG_Status!$H$2:$H$100000=S_Curve_Data!AH3) * (DRG_Status!$B$2:$B$100000=S_Curve_Data!$AH$1) )),0)/$AI$1} -> 0 | AK3: {=IFERROR(ROWS(_xlfn._xlws.FILTER( DRG_Status!$A$2:$A$100000, (DRG_Status!$I$2:$I$100000=S_Curve_Data!AH3) * (DRG_Status!$B$2:$B$100000=S_Curve_Data!$AH$1) )),0)/$AI$1} -> 0 | AL3: {=IFERROR(ROWS(_xlfn._xlws.FILTER( DRG_Status!$A$2:$A$100000, (DRG_Status!$J$2:$J$100000=S_Curve_Data!AH3) * (DRG_Status!$B$2:$B$100000=S_Curve_Data!$AH$1) )),0)/$AI$1} -> 0 | AO3: 45658 | AP3: {=IFERROR(ROWS(_xlfn._xlws.FILTER( DRG_Status!$A$2:$A$100000, (DRG_Status!$G$2:$G$100000=S_Curve_Data!AO3) * (DRG_Status!$B$2:$B$100000=S_Curve_Data!$AO$1) )),0)/$AP$1} -> #N/A | AQ3: {=IFERROR(ROWS(_xlfn._xlws.FILTER( DRG_Status!$A$2:$A$100000, (DRG_Status!$H$2:$H$100000=S_Curve_Data!AO3) * (DRG_Status!$B$2:$B$100000=S_Curve_Data!$AO$1) )),0)/$AP$1} -> #N/A | AR3: {=IFERROR(ROWS(_xlfn._xlws.FILTER( DRG_Status!$A$2:$A$100000, (DRG_Status!$I$2:$I$100000=S_Curve_Data!AO3) * (DRG_Status!$B$2:$B$100000=S_Curve_Data!$AO$1) )),0)/$AP$1} -> #N/A | AS3: {=IFERROR(ROWS(_xlfn._xlws.FILTER( DRG_Status!$A$2:$A$100000, (DRG_Status!$J$2:$J$100000=S_Curve_Data!AO3) * (DRG_Status!$B$2:$B$100000=S_Curve_Data!$AO$1) )),0)/$AP$1} -> #N/A
F4: =Mappings!B3 -> 45670 | G4: {=IFERROR(ROWS(_xlfn._xlws.FILTER( DRG_Status!$A$2:$A$100000, (DRG_Status!$C$2:$C$100000=S_Curve_Data!F4) * (DRG_Status!$B$2:$B$100000=S_Curve_Data!$F$1) )),0)/$G$1} -> 0 | H4: {=IFERROR(ROWS(_xlfn._xlws.FILTER( DRG_Status!$A$2:$A$100000, (DRG_Status!$D$2:$D$100000=S_Curve_Data!F4) * (DRG_Status!$B$2:$B$100000=S_Curve_Data!$F$1) )),0)/$G$1} -> 0 | I4: {=IFERROR(ROWS(_xlfn._xlws.FILTER( DRG_Status!$A$2:$A$100000, (DRG_Status!$E$2:$E$100000=S_Curve_Data!F4) * (DRG_Status!$B$2:$B$100000=S_Curve_Data!$F$1) )),0)/$G$1} -> 0 | J4: {=IFERROR(ROWS(_xlfn._xlws.FILTER( DRG_Status!$A$2:$A$100000, (DRG_Status!$F$2:$F$100000=S_Curve_Data!F4) * (DRG_Status!$B$2:$B$100000=S_Curve_Data!$F$1) )),0)/$G$1} -> 0 | M4: =Mappings!B3 -> 45670 | N4: {=IFERROR(ROWS(_xlfn._xlws.FILTER( DRG_Status!$A$2:$A$100000, (DRG_Status!$C$2:$C$100000=S_Curve_Data!M4) * (DRG_Status!$B$2:$B$100000=S_Curve_Data!$M$1) )),0)/$N$1} -> 0 | O4: {=IFERROR(ROWS(_xlfn._xlws.FILTER( DRG_Status!$A$2:$A$100000, (DRG_Status!$D$2:$D$100000=S_Curve_Data!M4) * (DRG_Status!$B$2:$B$100000=S_Curve_Data!$M$1) )),0)/$N$1} -> 0 | P4: {=IFERROR(ROWS(_xlfn._xlws.FILTER( DRG_Status!$A$2:$A$100000, (DRG_Status!$E$2:$E$100000=S_Curve_Data!M4) * (DRG_Status!$B$2:$B$100000=S_Curve_Data!$M$1) )),0)/$N$1} -> 0 | Q4: {=IFERROR(ROWS(_xlfn._xlws.FILTER( DRG_Status!$A$2:$A$100000, (DRG_Status!$F$2:$F$100000=S_Curve_Data!M4) * (DRG_Status!$B$2:$B$100000=S_Curve_Data!$M$1) )),0)/$N$1} -> 0 | T4: =Mappings!B3 -> 45670 | U4: {=IFERROR(ROWS(_xlfn._xlws.FILTER( DRG_Status!$A$2:$A$100000, (DRG_Status!$C$2:$C$100000=S_Curve_Data!T4) * (DRG_Status!$B$2:$B$100000=S_Curve_Data!$T$1) )),0)/$U$1} -> #N/A | V4: {=IFERROR(ROWS(_xlfn._xlws.FILTER( DRG_Status!$A$2:$A$100000, (DRG_Status!$D$2:$D$100000=S_Curve_Data!T4) * (DRG_Status!$B$2:$B$100000=S_Curve_Data!$T$1) )),0)/$U$1} -> #N/A | W4: {=IFERROR(ROWS(_xlfn._xlws.FILTER( DRG_Status!$A$2:$A$100000, (DRG_Status!$E$2:$E$100000=S_Curve_Data!T4) * (DRG_Status!$B$2:$B$100000=S_Curve_Data!$T$1) )),0)/$U$1} -> #N/A | X4: {=IFERROR(ROWS(_xlfn._xlws.FILTER( DRG_Status!$A$2:$A$100000, (DRG_Status!$F$2:$F$100000=S_Curve_Data!T4) * (DRG_Status!$B$2:$B$100000=S_Curve_Data!$T$1) )),0)/$U$1} -> #N/A | AA4: 45689 | AB4: {=IFERROR(ROWS(_xlfn._xlws.FILTER( DRG_Status!$A$2:$A$100000, (DRG_Status!$G$2:$G$100000=S_Curve_Data!AA4) * (DRG_Status!$B$2:$B$100000=S_Curve_Data!$AA$1) )),0)/$AB$1} -> 0 | AC4: {=IFERROR(ROWS(_xlfn._xlws.FILTER( DRG_Status!$A$2:$A$100000, (DRG_Status!$H$2:$H$100000=S_Curve_Data!AA4) * (DRG_Status!$B$2:$B$100000=S_Curve_Data!$AA$1) )),0)/$AB$1} -> 0 | AD4: {=IFERROR(ROWS(_xlfn._xlws.FILTER( DRG_Status!$A$2:$A$100000, (DRG_Status!$I$2:$I$100000=S_Curve_Data!AA4) * (DRG_Status!$B$2:$B$100000=S_Curve_Data!$AA$1) )),0)/$AB$1} -> 0 | AE4: {=IFERROR(ROWS(_xlfn._xlws.FILTER( DRG_Status!$A$2:$A$100000, (DRG_Status!$J$2:$J$100000=S_Curve_Data!AA4) * (DRG_Status!$B$2:$B$100000=S_Curve_Data!$AA$1) )),0)/$AB$1} -> 0 | AH4: 45689 | AI4: {=IFERROR(ROWS(_xlfn._xlws.FILTER( DRG_Status!$A$2:$A$100000, (DRG_Status!$G$2:$G$100000=S_Curve_Data!AH4) * (DRG_Status!$B$2:$B$100000=S_Curve_Data!$AH$1) )),0)/$AI$1} -> 0 | AJ4: {=IFERROR(ROWS(_xlfn._xlws.FILTER( DRG_Status!$A$2:$A$100000, (DRG_Status!$H$2:$H$100000=S_Curve_Data!AH4) * (DRG_Status!$B$2:$B$100000=S_Curve_Data!$AH$1) )),0)/$AI$1} -> 0 | AK4: {=IFERROR(ROWS(_xlfn._xlws.FILTER( DRG_Status!$A$2:$A$100000, (DRG_Status!$I$2:$I$100000=S_Curve_Data!AH4) * (DRG_Status!$B$2:$B$100000=S_Curve_Data!$AH$1) )),0)/$AI$1} -> 0 | AL4: {=IFERROR(ROWS(_xlfn._xlws.FILTER( DRG_Status!$A$2:$A$100000, (DRG_Status!$J$2:$J$100000=S_Curve_Data!AH4) * (DRG_Status!$B$2:$B$100000=S_Curve_Data!$AH$1) )),0)/$AI$1} -> 0 | AO4: 45689 | AP4: {=IFERROR(ROWS(_xlfn._xlws.FILTER( DRG_Status!$A$2:$A$100000, (DRG_Status!$G$2:$G$100000=S_Curve_Data!AO4) * (DRG_Status!$B$2:$B$100000=S_Curve_Data!$AO$1) )),0)/$AP$1} -> #N/A | AQ4: {=IFERROR(ROWS(_xlfn._xlws.FILTER( DRG_Status!$A$2:$A$100000, (DRG_Status!$H$2:$H$100000=S_Curve_Data!AO4) * (DRG_Status!$B$2:$B$100000=S_Curve_Data!$AO$1) )),0)/$AP$1} -> #N/A | AR4: {=IFERROR(ROWS(_xlfn._xlws.FILTER( DRG_Status!$A$2:$A$100000, (DRG_Status!$I$2:$I$100000=S_Curve_Data!AO4) * (DRG_Status!$B$2:$B$100000=S_Curve_Data!$AO$1) )),0)/$AP$1} -> #N/A | AS4: {=IFERROR(ROWS(_xlfn._xlws.FILTER( DRG_Status!$A$2:$A$100000, (DRG_Status!$J$2:$J$100000=S_Curve_Data!AO4) * (DRG_Status!$B$2:$B$100000=S_Curve_Data!$AO$1) )),0)/$AP$1} -> #N/A
F5: =Mappings!B4 -> 45677 | G5: {=IFERROR(ROWS(_xlfn._xlws.FILTER( DRG_Status!$A$2:$A$100000, (DRG_Status!$C$2:$C$100000=S_Curve_Data!F5) * (DRG_Status!$B$2:$B$100000=S_Curve_Data!$F$1) )),0)/$G$1} -> 0 | H5: {=IFERROR(ROWS(_xlfn._xlws.FILTER( DRG_Status!$A$2:$A$100000, (DRG_Status!$D$2:$D$100000=S_Curve_Data!F5) * (DRG_Status!$B$2:$B$100000=S_Curve_Data!$F$1) )),0)/$G$1} -> 0 | I5: {=IFERROR(ROWS(_xlfn._xlws.FILTER( DRG_Status!$A$2:$A$100000, (DRG_Status!$E$2:$E$100000=S_Curve_Data!F5) * (DRG_Status!$B$2:$B$100000=S_Curve_Data!$F$1) )),0)/$G$1} -> 0 | J5: {=IFERROR(ROWS(_xlfn._xlws.FILTER( DRG_Status!$A$2:$A$100000, (DRG_Status!$F$2:$F$100000=S_Curve_Data!F5) * (DRG_Status!$B$2:$B$100000=S_Curve_Data!$F$1) )),0)/$G$1} -> 0 | M5: =Mappings!B4 -> 45677 | N5: {=IFERROR(ROWS(_xlfn._xlws.FILTER( DRG_Status!$A$2:$A$100000, (DRG_Status!$C$2:$C$100000=S_Curve_Data!M5) * (DRG_Status!$B$2:$B$100000=S_Curve_Data!$M$1) )),0)/$N$1} -> 0 | O5: {=IFERROR(ROWS(_xlfn._xlws.FILTER( DRG_Status!$A$2:$A$100000, (DRG_Status!$D$2:$D$100000=S_Curve_Data!M5) * (DRG_Status!$B$2:$B$100000=S_Curve_Data!$M$1) )),0)/$N$1} -> 0 | P5: {=IFERROR(ROWS(_xlfn._xlws.FILTER( DRG_Status!$A$2:$A$100000, (DRG_Status!$E$2:$E$100000=S_Curve_Data!M5) * (DRG_Status!$B$2:$B$100000=S_Curve_Data!$M$1) )),0)/$N$1} -> 0 | Q5: {=IFERROR(ROWS(_xlfn._xlws.FILTER( DRG_Status!$A$2:$A$100000, (DRG_Status!$F$2:$F$100000=S_Curve_Data!M5) * (DRG_Status!$B$2:$B$100000=S_Curve_Data!$M$1) )),0)/$N$1} -> 0 | T5: =Mappings!B4 -> 45677 | U5: {=IFERROR(ROWS(_xlfn._xlws.FILTER( DRG_Status!$A$2:$A$100000, (DRG_Status!$C$2:$C$100000=S_Curve_Data!T5) * (DRG_Status!$B$2:$B$100000=S_Curve_Data!$T$1) )),0)/$U$1} -> #N/A | V5: {=IFERROR(ROWS(_xlfn._xlws.FILTER( DRG_Status!$A$2:$A$100000, (DRG_Status!$D$2:$D$100000=S_Curve_Data!T5) * (DRG_Status!$B$2:$B$100000=S_Curve_Data!$T$1) )),0)/$U$1} -> #N/A | W5: {=IFERROR(ROWS(_xlfn._xlws.FILTER( DRG_Status!$A$2:$A$100000, (DRG_Status!$E$2:$E$100000=S_Curve_Data!T5) * (DRG_Status!$B$2:$B$100000=S_Curve_Data!$T$1) )),0)/$U$1} -> #N/A | X5: {=IFERROR(ROWS(_xlfn._xlws.FILTER( DRG_Status!$A$2:$A$100000, (DRG_Status!$F$2:$F$100000=S_Curve_Data!T5) * (DRG_Status!$B$2:$B$100000=S_Curve_Data!$T$1) )),0)/$U$1} -> #N/A | AA5: 45717 | AB5: {=IFERROR(ROWS(_xlfn._xlws.FILTER( DRG_Status!$A$2:$A$100000, (DRG_Status!$G$2:$G$100000=S_Curve_Data!AA5) * (DRG_Status!$B$2:$B$100000=S_Curve_Data!$AA$1) )),0)/$AB$1} -> 0 | AC5: {=IFERROR(ROWS(_xlfn._xlws.FILTER( DRG_Status!$A$2:$A$100000, (DRG_Status!$H$2:$H$100000=S_Curve_Data!AA5) * (DRG_Status!$B$2:$B$100000=S_Curve_Data!$AA$1) )),0)/$AB$1} -> 0 | AD5: {=IFERROR(ROWS(_xlfn._xlws.FILTER( DRG_Status!$A$2:$A$100000, (DRG_Status!$I$2:$I$100000=S_Curve_Data!AA5) * (DRG_Status!$B$2:$B$100000=S_Curve_Data!$AA$1) )),0)/$AB$1} -> 0 | AE5: {=IFERROR(ROWS(_xlfn._xlws.FILTER( DRG_Status!$A$2:$A$100000, (DRG_Status!$J$2:$J$100000=S_Curve_Data!AA5) * (DRG_Status!$B$2:$B$100000=S_Curve_Data!$AA$1) )),0)/$AB$1} -> 0 | AH5: 45717 | AI5: {=IFERROR(ROWS(_xlfn._xlws.FILTER( DRG_Status!$A$2:$A$100000, (DRG_Status!$G$2:$G$100000=S_Curve_Data!AH5) * (DRG_Status!$B$2:$B$100000=S_Curve_Data!$AH$1) )),0)/$AI$1} -> 0 | AJ5: {=IFERROR(ROWS(_xlfn._xlws.FILTER( DRG_Status!$A$2:$A$100000, (DRG_Status!$H$2:$H$100000=S_Curve_Data!AH5) * (DRG_Status!$B$2:$B$100000=S_Curve_Data!$AH$1) )),0)/$AI$1} -> 0 | AK5: {=IFERROR(ROWS(_xlfn._xlws.FILTER( DRG_Status!$A$2:$A$100000, (DRG_Status!$I$2:$I$100000=S_Curve_Data!AH5) * (DRG_Status!$B$2:$B$100000=S_Curve_Data!$AH$1) )),0)/$AI$1} -> 0 | AL5: {=IFERROR(ROWS(_xlfn._xlws.FILTER( DRG_Status!$A$2:$A$100000, (DRG_Status!$J$2:$J$100000=S_Curve_Data!AH5) * (DRG_Status!$B$2:$B$100000=S_Curve_Data!$AH$1) )),0)/$AI$1} -> 0 | AO5: 45717 | AP5: {=IFERROR(ROWS(_xlfn._xlws.FILTER( DRG_Status!$A$2:$A$100000, (DRG_Status!$G$2:$G$100000=S_Curve_Data!AO5) * (DRG_Status!$B$2:$B$100000=S_Curve_Data!$AO$1) )),0)/$AP$1} -> #N/A | AQ5: {=IFERROR(ROWS(_xlfn._xlws.FILTER( DRG_Status!$A$2:$A$100000, (DRG_Status!$H$2:$H$100000=S_Curve_Data!AO5) * (DRG_Status!$B$2:$B$100000=S_Curve_Data!$AO$1) )),0)/$AP$1} -> #N/A | AR5: {=IFERROR(ROWS(_xlfn._xlws.FILTER( DRG_Status!$A$2:$A$100000, (DRG_Status!$I$2:$I$100000=S_Curve_Data!AO5) * (DRG_Status!$B$2:$B$100000=S_Curve_Data!$AO$1) )),0)/$AP$1} -> #N/A | AS5: {=IFERROR(ROWS(_xlfn._xlws.FILTER( DRG_Status!$A$2:$A$100000, (DRG_Status!$J$2:$J$100000=S_Curve_Data!AO5) * (DRG_Status!$B$2:$B$100000=S_Curve_Data!$AO$1) )),0)/$AP$1} -> #N/A
F6: =Mappings!B5 -> 45684 | G6: {=IFERROR(ROWS(_xlfn._xlws.FILTER( DRG_Status!$A$2:$A$100000, (DRG_Status!$C$2:$C$100000=S_Curve_Data!F6) * (DRG_Status!$B$2:$B$100000=S_Curve_Data!$F$1) )),0)/$G$1} -> 0 | H6: {=IFERROR(ROWS(_xlfn._xlws.FILTER( DRG_Status!$A$2:$A$100000, (DRG_Status!$D$2:$D$100000=S_Curve_Data!F6) * (DRG_Status!$B$2:$B$100000=S_Curve_Data!$F$1) )),0)/$G$1} -> 0 | I6: {=IFERROR(ROWS(_xlfn._xlws.FILTER( DRG_Status!$A$2:$A$100000, (DRG_Status!$E$2:$E$100000=S_Curve_Data!F6) * (DRG_Status!$B$2:$B$100000=S_Curve_Data!$F$1) )),0)/$G$1} -> 0 | J6: {=IFERROR(ROWS(_xlfn._xlws.FILTER( DRG_Status!$A$2:$A$100000, (DRG_Status!$F$2:$F$100000=S_Curve_Data!F6) * (DRG_Status!$B$2:$B$100000=S_Curve_Data!$F$1) )),0)/$G$1} -> 0 | M6: =Mappings!B5 -> 45684 | N6: {=IFERROR(ROWS(_xlfn._xlws.FILTER( DRG_Status!$A$2:$A$100000, (DRG_Status!$C$2:$C$100000=S_Curve_Data!M6) * (DRG_Status!$B$2:$B$100000=S_Curve_Data!$M$1) )),0)/$N$1} -> 0 | O6: {=IFERROR(ROWS(_xlfn._xlws.FILTER( DRG_Status!$A$2:$A$100000, (DRG_Status!$D$2:$D$100000=S_Curve_Data!M6) * (DRG_Status!$B$2:$B$100000=S_Curve_Data!$M$1) )),0)/$N$1} -> 0 | P6: {=IFERROR(ROWS(_xlfn._xlws.FILTER( DRG_Status!$A$2:$A$100000, (DRG_Status!$E$2:$E$100000=S_Curve_Data!M6) * (DRG_Status!$B$2:$B$100000=S_Curve_Data!$M$1) )),0)/$N$1} -> 0 | Q6: {=IFERROR(ROWS(_xlfn._xlws.FILTER( DRG_Status!$A$2:$A$100000, (DRG_Status!$F$2:$F$100000=S_Curve_Data!M6) * (DRG_Status!$B$2:$B$100000=S_Curve_Data!$M$1) )),0)/$N$1} -> 0 | T6: =Mappings!B5 -> 45684 | U6: {=IFERROR(ROWS(_xlfn._xlws.FILTER( DRG_Status!$A$2:$A$100000, (DRG_Status!$C$2:$C$100000=S_Curve_Data!T6) * (DRG_Status!$B$2:$B$100000=S_Curve_Data!$T$1) )),0)/$U$1} -> #N/A | V6: {=IFERROR(ROWS(_xlfn._xlws.FILTER( DRG_Status!$A$2:$A$100000, (DRG_Status!$D$2:$D$100000=S_Curve_Data!T6) * (DRG_Status!$B$2:$B$100000=S_Curve_Data!$T$1) )),0)/$U$1} -> #N/A | W6: {=IFERROR(ROWS(_xlfn._xlws.FILTER( DRG_Status!$A$2:$A$100000, (DRG_Status!$E$2:$E$100000=S_Curve_Data!T6) * (DRG_Status!$B$2:$B$100000=S_Curve_Data!$T$1) )),0)/$U$1} -> #N/A | X6: {=IFERROR(ROWS(_xlfn._xlws.FILTER( DRG_Status!$A$2:$A$100000, (DRG_Status!$F$2:$F$100000=S_Curve_Data!T6) * (DRG_Status!$B$2:$B$100000=S_Curve_Data!$T$1) )),0)/$U$1} -> #N/A | AA6: 45748 | AB6: {=IFERROR(ROWS(_xlfn._xlws.FILTER( DRG_Status!$A$2:$A$100000, (DRG_Status!$G$2:$G$100000=S_Curve_Data!AA6) * (DRG_Status!$B$2:$B$100000=S_Curve_Data!$AA$1) )),0)/$AB$1} -> 0 | AC6: {=IFERROR(ROWS(_xlfn._xlws.FILTER( DRG_Status!$A$2:$A$100000, (DRG_Status!$H$2:$H$100000=S_Curve_Data!AA6) * (DRG_Status!$B$2:$B$100000=S_Curve_Data!$AA$1) )),0)/$AB$1} -> 0 | AD6: {=IFERROR(ROWS(_xlfn._xlws.FILTER( DRG_Status!$A$2:$A$100000, (DRG_Status!$I$2:$I$100000=S_Curve_Data!AA6) * (DRG_Status!$B$2:$B$100000=S_Curve_Data!$AA$1) )),0)/$AB$1} -> 0 | AE6: {=IFERROR(ROWS(_xlfn._xlws.FILTER( DRG_Status!$A$2:$A$100000, (DRG_Status!$J$2:$J$100000=S_Curve_Data!AA6) * (DRG_Status!$B$2:$B$100000=S_Curve_Data!$AA$1) )),0)/$AB$1} -> 0 | AH6: 45748 | AI6: {=IFERROR(ROWS(_xlfn._xlws.FILTER( DRG_Status!$A$2:$A$100000, (DRG_Status!$G$2:$G$100000=S_Curve_Data!AH6) * (DRG_Status!$B$2:$B$100000=S_Curve_Data!$AH$1) )),0)/$AI$1} -> 0 | AJ6: {=IFERROR(ROWS(_xlfn._xlws.FILTER( DRG_Status!$A$2:$A$100000, (DRG_Status!$H$2:$H$100000=S_Curve_Data!AH6) * (DRG_Status!$B$2:$B$100000=S_Curve_Data!$AH$1) )),0)/$AI$1} -> 0 | AK6: {=IFERROR(ROWS(_xlfn._xlws.FILTER( DRG_Status!$A$2:$A$100000, (DRG_Status!$I$2:$I$100000=S_Curve_Data!AH6) * (DRG_Status!$B$2:$B$100000=S_Curve_Data!$AH$1) )),0)/$AI$1} -> 0 | AL6: {=IFERROR(ROWS(_xlfn._xlws.FILTER( DRG_Status!$A$2:$A$100000, (DRG_Status!$J$2:$J$100000=S_Curve_Data!AH6) * (DRG_Status!$B$2:$B$100000=S_Curve_Data!$AH$1) )),0)/$AI$1} -> 0 | AO6: 45748 | AP6: {=IFERROR(ROWS(_xlfn._xlws.FILTER( DRG_Status!$A$2:$A$100000, (DRG_Status!$G$2:$G$100000=S_Curve_Data!AO6) * (DRG_Status!$B$2:$B$100000=S_Curve_Data!$AO$1) )),0)/$AP$1} -> #N/A | AQ6: {=IFERROR(ROWS(_xlfn._xlws.FILTER( DRG_Status!$A$2:$A$100000, (DRG_Status!$H$2:$H$100000=S_Curve_Data!AO6) * (DRG_Status!$B$2:$B$100000=S_Curve_Data!$AO$1) )),0)/$AP$1} -> #N/A | AR6: {=IFERROR(ROWS(_xlfn._xlws.FILTER( DRG_Status!$A$2:$A$100000, (DRG_Status!$I$2:$I$100000=S_Curve_Data!AO6) * (DRG_Status!$B$2:$B$100000=S_Curve_Data!$AO$1) )),0)/$AP$1} -> #N/A | AS6: {=IFERROR(ROWS(_xlfn._xlws.FILTER( DRG_Status!$A$2:$A$100000, (DRG_Status!$J$2:$J$100000=S_Curve_Data!AO6) * (DRG_Status!$B$2:$B$100000=S_Curve_Data!$AO$1) )),0)/$AP$1} -> #N/A
F7: =Mappings!B6 -> 45691 | G7: {=IFERROR(ROWS(_xlfn._xlws.FILTER( DRG_Status!$A$2:$A$100000, (DRG_Status!$C$2:$C$100000=S_Curve_Data!F7) * (DRG_Status!$B$2:$B$100000=S_Curve_Data!$F$1) )),0)/$G$1} -> 0 | H7: {=IFERROR(ROWS(_xlfn._xlws.FILTER( DRG_Status!$A$2:$A$100000, (DRG_Status!$D$2:$D$100000=S_Curve_Data!F7) * (DRG_Status!$B$2:$B$100000=S_Curve_Data!$F$1) )),0)/$G$1} -> 0 | I7: {=IFERROR(ROWS(_xlfn._xlws.FILTER( DRG_Status!$A$2:$A$100000, (DRG_Status!$E$2:$E$100000=S_Curve_Data!F7) * (DRG_Status!$B$2:$B$100000=S_Curve_Data!$F$1) )),0)/$G$1} -> 0 | J7: {=IFERROR(ROWS(_xlfn._xlws.FILTER( DRG_Status!$A$2:$A$100000, (DRG_Status!$F$2:$F$100000=S_Curve_Data!F7) * (DRG_Status!$B$2:$B$100000=S_Curve_Data!$F$1) )),0)/$G$1} -> 0 | M7: =Mappings!B6 -> 45691 | N7: {=IFERROR(ROWS(_xlfn._xlws.FILTER( DRG_Status!$A$2:$A$100000, (DRG_Status!$C$2:$C$100000=S_Curve_Data!M7) * (DRG_Status!$B$2:$B$100000=S_Curve_Data!$M$1) )),0)/$N$1} -> 0 | O7: {=IFERROR(ROWS(_xlfn._xlws.FILTER( DRG_Status!$A$2:$A$100000, (DRG_Status!$D$2:$D$100000=S_Curve_Data!M7) * (DRG_Status!$B$2:$B$100000=S_Curve_Data!$M$1) )),0)/$N$1} -> 0 | P7: {=IFERROR(ROWS(_xlfn._xlws.FILTER( DRG_Status!$A$2:$A$100000, (DRG_Status!$E$2:$E$100000=S_Curve_Data!M7) * (DRG_Status!$B$2:$B$100000=S_Curve_Data!$M$1) )),0)/$N$1} -> 0 | Q7: {=IFERROR(ROWS(_xlfn._xlws.FILTER( DRG_Status!$A$2:$A$100000, (DRG_Status!$F$2:$F$100000=S_Curve_Data!M7) * (DRG_Status!$B$2:$B$100000=S_Curve_Data!$M$1) )),0)/$N$1} -> 0 | T7: =Mappings!B6 -> 45691 | U7: {=IFERROR(ROWS(_xlfn._xlws.FILTER( DRG_Status!$A$2:$A$100000, (DRG_Status!$C$2:$C$100000=S_Curve_Data!T7) * (DRG_Status!$B$2:$B$100000=S_Curve_Data!$T$1) )),0)/$U$1} -> #N/A | V7: {=IFERROR(ROWS(_xlfn._xlws.FILTER( DRG_Status!$A$2:$A$100000, (DRG_Status!$D$2:$D$100000=S_Curve_Data!T7) * (DRG_Status!$B$2:$B$100000=S_Curve_Data!$T$1) )),0)/$U$1} -> #N/A | W7: {=IFERROR(ROWS(_xlfn._xlws.FILTER( DRG_Status!$A$2:$A$100000, (DRG_Status!$E$2:$E$100000=S_Curve_Data!T7) * (DRG_Status!$B$2:$B$100000=S_Curve_Data!$T$1) )),0)/$U$1} -> #N/A | X7: {=IFERROR(ROWS(_xlfn._xlws.FILTER( DRG_Status!$A$2:$A$100000, (DRG_Status!$F$2:$F$100000=S_Curve_Data!T7) * (DRG_Status!$B$2:$B$100000=S_Curve_Data!$T$1) )),0)/$U$1} -> #N/A | AA7: 45778 | AB7: {=IFERROR(ROWS(_xlfn._xlws.FILTER( DRG_Status!$A$2:$A$100000, (DRG_Status!$G$2:$G$100000=S_Curve_Data!AA7) * (DRG_Status!$B$2:$B$100000=S_Curve_Data!$AA$1) )),0)/$AB$1} -> 0 | AC7: {=IFERROR(ROWS(_xlfn._xlws.FILTER( DRG_Status!$A$2:$A$100000, (DRG_Status!$H$2:$H$100000=S_Curve_Data!AA7) * (DRG_Status!$B$2:$B$100000=S_Curve_Data!$AA$1) )),0)/$AB$1} -> 0 | AD7: {=IFERROR(ROWS(_xlfn._xlws.FILTER( DRG_Status!$A$2:$A$100000, (DRG_Status!$I$2:$I$100000=S_Curve_Data!AA7) * (DRG_Status!$B$2:$B$100000=S_Curve_Data!$AA$1) )),0)/$AB$1} -> 0 | AE7: {=IFERROR(ROWS(_xlfn._xlws.FILTER( DRG_Status!$A$2:$A$100000, (DRG_Status!$J$2:$J$100000=S_Curve_Data!AA7) * (DRG_Status!$B$2:$B$100000=S_Curve_Data!$AA$1) )),0)/$AB$1} -> 0 | AH7: 45778 | AI7: {=IFERROR(ROWS(_xlfn._xlws.FILTER( DRG_Status!$A$2:$A$100000, (DRG_Status!$G$2:$G$100000=S_Curve_Data!AH7) * (DRG_Status!$B$2:$B$100000=S_Curve_Data!$AH$1) )),0)/$AI$1} -> 0 | AJ7: {=IFERROR(ROWS(_xlfn._xlws.FILTER( DRG_Status!$A$2:$A$100000, (DRG_Status!$H$2:$H$100000=S_Curve_Data!AH7) * (DRG_Status!$B$2:$B$100000=S_Curve_Data!$AH$1) )),0)/$AI$1} -> 0 | AK7: {=IFERROR(ROWS(_xlfn._xlws.FILTER( DRG_Status!$A$2:$A$100000, (DRG_Status!$I$2:$I$100000=S_Curve_Data!AH7) * (DRG_Status!$B$2:$B$100000=S_Curve_Data!$AH$1) )),0)/$AI$1} -> 0 | AL7: {=IFERROR(ROWS(_xlfn._xlws.FILTER( DRG_Status!$A$2:$A$100000, (DRG_Status!$J$2:$J$100000=S_Curve_Data!AH7) * (DRG_Status!$B$2:$B$100000=S_Curve_Data!$AH$1) )),0)/$AI$1} -> 0 | AO7: 45778 | AP7: {=IFERROR(ROWS(_xlfn._xlws.FILTER( DRG_Status!$A$2:$A$100000, (DRG_Status!$G$2:$G$100000=S_Curve_Data!AO7) * (DRG_Status!$B$2:$B$100000=S_Curve_Data!$AO$1) )),0)/$AP$1} -> #N/A | AQ7: {=IFERROR(ROWS(_xlfn._xlws.FILTER( DRG_Status!$A$2:$A$100000, (DRG_Status!$H$2:$H$100000=S_Curve_Data!AO7) * (DRG_Status!$B$2:$B$100000=S_Curve_Data!$AO$1) )),0)/$AP$1} -> #N/A | AR7: {=IFERROR(ROWS(_xlfn._xlws.FILTER( DRG_Status!$A$2:$A$100000, (DRG_Status!$I$2:$I$100000=S_Curve_Data!AO7) * (DRG_Status!$B$2:$B$100000=S_Curve_Data!$AO$1) )),0)/$AP$1} -> #N/A | AS7: {=IFERROR(ROWS(_xlfn._xlws.FILTER( DRG_Status!$A$2:$A$100000, (DRG_Status!$J$2:$J$100000=S_Curve_Data!AO7) * (DRG_Status!$B$2:$B$100000=S_Curve_Data!$AO$1) )),0)/$AP$1} -> #N/A
F8: =Mappings!B7 -> 45698 | G8: {=IFERROR(ROWS(_xlfn._xlws.FILTER( DRG_Status!$A$2:$A$100000, (DRG_Status!$C$2:$C$100000=S_Curve_Data!F8) * (DRG_Status!$B$2:$B$100000=S_Curve_Data!$F$1) )),0)/$G$1} -> 0 | H8: {=IFERROR(ROWS(_xlfn._xlws.FILTER( DRG_Status!$A$2:$A$100000, (DRG_Status!$D$2:$D$100000=S_Curve_Data!F8) * (DRG_Status!$B$2:$B$100000=S_Curve_Data!$F$1) )),0)/$G$1} -> 0 | I8: {=IFERROR(ROWS(_xlfn._xlws.FILTER( DRG_Status!$A$2:$A$100000, (DRG_Status!$E$2:$E$100000=S_Curve_Data!F8) * (DRG_Status!$B$2:$B$100000=S_Curve_Data!$F$1) )),0)/$G$1} -> 0 | J8: {=IFERROR(ROWS(_xlfn._xlws.FILTER( DRG_Status!$A$2:$A$100000, (DRG_Status!$F$2:$F$100000=S_Curve_Data!F8) * (DRG_Status!$B$2:$B$100000=S_Curve_Data!$F$1) )),0)/$G$1} -> 0 | M8: =Mappings!B7 -> 45698 | N8: {=IFERROR(ROWS(_xlfn._xlws.FILTER( DRG_Status!$A$2:$A$100000, (DRG_Status!$C$2:$C$100000=S_Curve_Data!M8) * (DRG_Status!$B$2:$B$100000=S_Curve_Data!$M$1) )),0)/$N$1} -> 0 | O8: {=IFERROR(ROWS(_xlfn._xlws.FILTER( DRG_Status!$A$2:$A$100000, (DRG_Status!$D$2:$D$100000=S_Curve_Data!M8) * (DRG_Status!$B$2:$B$100000=S_Curve_Data!$M$1) )),0)/$N$1} -> 0 | P8: {=IFERROR(ROWS(_xlfn._xlws.FILTER( DRG_Status!$A$2:$A$100000, (DRG_Status!$E$2:$E$100000=S_Curve_Data!M8) * (DRG_Status!$B$2:$B$100000=S_Curve_Data!$M$1) )),0)/$N$1} -> 0 | Q8: {=IFERROR(ROWS(_xlfn._xlws.FILTER( DRG_Status!$A$2:$A$100000, (DRG_Status!$F$2:$F$100000=S_Curve_Data!M8) * (DRG_Status!$B$2:$B$100000=S_Curve_Data!$M$1) )),0)/$N$1} -> 0 | T8: =Mappings!B7 -> 45698 | U8: {=IFERROR(ROWS(_xlfn._xlws.FILTER( DRG_Status!$A$2:$A$100000, (DRG_Status!$C$2:$C$100000=S_Curve_Data!T8) * (DRG_Status!$B$2:$B$100000=S_Curve_Data!$T$1) )),0)/$U$1} -> #N/A | V8: {=IFERROR(ROWS(_xlfn._xlws.FILTER( DRG_Status!$A$2:$A$100000, (DRG_Status!$D$2:$D$100000=S_Curve_Data!T8) * (DRG_Status!$B$2:$B$100000=S_Curve_Data!$T$1) )),0)/$U$1} -> #N/A | W8: {=IFERROR(ROWS(_xlfn._xlws.FILTER( DRG_Status!$A$2:$A$100000, (DRG_Status!$E$2:$E$100000=S_Curve_Data!T8) * (DRG_Status!$B$2:$B$100000=S_Curve_Data!$T$1) )),0)/$U$1} -> #N/A | X8: {=IFERROR(ROWS(_xlfn._xlws.FILTER( DRG_Status!$A$2:$A$100000, (DRG_Status!$F$2:$F$100000=S_Curve_Data!T8) * (DRG_Status!$B$2:$B$100000=S_Curve_Data!$T$1) )),0)/$U$1} -> #N/A | AA8: 45809 | AB8: {=IFERROR(ROWS(_xlfn._xlws.FILTER( DRG_Status!$A$2:$A$100000, (DRG_Status!$G$2:$G$100000=S_Curve_Data!AA8) * (DRG_Status!$B$2:$B$100000=S_Curve_Data!$AA$1) )),0)/$AB$1} -> 0 | AC8: {=IFERROR(ROWS(_xlfn._xlws.FILTER( DRG_Status!$A$2:$A$100000, (DRG_Status!$H$2:$H$100000=S_Curve_Data!AA8) * (DRG_Status!$B$2:$B$100000=S_Curve_Data!$AA$1) )),0)/$AB$1} -> 0 | AD8: {=IFERROR(ROWS(_xlfn._xlws.FILTER( DRG_Status!$A$2:$A$100000, (DRG_Status!$I$2:$I$100000=S_Curve_Data!AA8) * (DRG_Status!$B$2:$B$100000=S_Curve_Data!$AA$1) )),0)/$AB$1} -> 0 | AE8: {=IFERROR(ROWS(_xlfn._xlws.FILTER( DRG_Status!$A$2:$A$100000, (DRG_Status!$J$2:$J$100000=S_Curve_Data!AA8) * (DRG_Status!$B$2:$B$100000=S_Curve_Data!$AA$1) )),0)/$AB$1} -> 0 | AH8: 45809 | AI8: {=IFERROR(ROWS(_xlfn._xlws.FILTER( DRG_Status!$A$2:$A$100000, (DRG_Status!$G$2:$G$100000=S_Curve_Data!AH8) * (DRG_Status!$B$2:$B$100000=S_Curve_Data!$AH$1) )),0)/$AI$1} -> 0 | AJ8: {=IFERROR(ROWS(_xlfn._xlws.FILTER( DRG_Status!$A$2:$A$100000, (DRG_Status!$H$2:$H$100000=S_Curve_Data!AH8) * (DRG_Status!$B$2:$B$100000=S_Curve_Data!$AH$1) )),0)/$AI$1} -> 0 | AK8: {=IFERROR(ROWS(_xlfn._xlws.FILTER( DRG_Status!$A$2:$A$100000, (DRG_Status!$I$2:$I$100000=S_Curve_Data!AH8) * (DRG_Status!$B$2:$B$100000=S_Curve_Data!$AH$1) )),0)/$AI$1} -> 0 | AL8: {=IFERROR(ROWS(_xlfn._xlws.FILTER( DRG_Status!$A$2:$A$100000, (DRG_Status!$J$2:$J$100000=S_Curve_Data!AH8) * (DRG_Status!$B$2:$B$100000=S_Curve_Data!$AH$1) )),0)/$AI$1} -> 0 | AO8: 45809 | AP8: {=IFERROR(ROWS(_xlfn._xlws.FILTER( DRG_Status!$A$2:$A$100000, (DRG_Status!$G$2:$G$100000=S_Curve_Data!AO8) * (DRG_Status!$B$2:$B$100000=S_Curve_Data!$AO$1) )),0)/$AP$1} -> #N/A | AQ8: {=IFERROR(ROWS(_xlfn._xlws.FILTER( DRG_Status!$A$2:$A$100000, (DRG_Status!$H$2:$H$100000=S_Curve_Data!AO8) * (DRG_Status!$B$2:$B$100000=S_Curve_Data!$AO$1) )),0)/$AP$1} -> #N/A | AR8: {=IFERROR(ROWS(_xlfn._xlws.FILTER( DRG_Status!$A$2:$A$100000, (DRG_Status!$I$2:$I$100000=S_Curve_Data!AO8) * (DRG_Status!$B$2:$B$100000=S_Curve_Data!$AO$1) )),0)/$AP$1} -> #N/A | AS8: {=IFERROR(ROWS(_xlfn._xlws.FILTER( DRG_Status!$A$2:$A$100000, (DRG_Status!$J$2:$J$100000=S_Curve_Data!AO8) * (DRG_Status!$B$2:$B$100000=S_Curve_Data!$AO$1) )),0)/$AP$1} -> #N/A
F9: =Mappings!B8 -> 45705 | G9: {=IFERROR(ROWS(_xlfn._xlws.FILTER( DRG_Status!$A$2:$A$100000, (DRG_Status!$C$2:$C$100000=S_Curve_Data!F9) * (DRG_Status!$B$2:$B$100000=S_Curve_Data!$F$1) )),0)/$G$1} -> 0 | H9: {=IFERROR(ROWS(_xlfn._xlws.FILTER( DRG_Status!$A$2:$A$100000, (DRG_Status!$D$2:$D$100000=S_Curve_Data!F9) * (DRG_Status!$B$2:$B$100000=S_Curve_Data!$F$1) )),0)/$G$1} -> 0 | I9: {=IFERROR(ROWS(_xlfn._xlws.FILTER( DRG_Status!$A$2:$A$100000, (DRG_Status!$E$2:$E$100000=S_Curve_Data!F9) * (DRG_Status!$B$2:$B$100000=S_Curve_Data!$F$1) )),0)/$G$1} -> 0 | J9: {=IFERROR(ROWS(_xlfn._xlws.FILTER( DRG_Status!$A$2:$A$100000, (DRG_Status!$F$2:$F$100000=S_Curve_Data!F9) * (DRG_Status!$B$2:$B$100000=S_Curve_Data!$F$1) )),0)/$G$1} -> 0 | M9: =Mappings!B8 -> 45705 | N9: {=IFERROR(ROWS(_xlfn._xlws.FILTER( DRG_Status!$A$2:$A$100000, (DRG_Status!$C$2:$C$100000=S_Curve_Data!M9) * (DRG_Status!$B$2:$B$100000=S_Curve_Data!$M$1) )),0)/$N$1} -> 0 | O9: {=IFERROR(ROWS(_xlfn._xlws.FILTER( DRG_Status!$A$2:$A$100000, (DRG_Status!$D$2:$D$100000=S_Curve_Data!M9) * (DRG_Status!$B$2:$B$100000=S_Curve_Data!$M$1) )),0)/$N$1} -> 0 | P9: {=IFERROR(ROWS(_xlfn._xlws.FILTER( DRG_Status!$A$2:$A$100000, (DRG_Status!$E$2:$E$100000=S_Curve_Data!M9) * (DRG_Status!$B$2:$B$100000=S_Curve_Data!$M$1) )),0)/$N$1} -> 0 | Q9: {=IFERROR(ROWS(_xlfn._xlws.FILTER( DRG_Status!$A$2:$A$100000, (DRG_Status!$F$2:$F$100000=S_Curve_Data!M9) * (DRG_Status!$B$2:$B$100000=S_Curve_Data!$M$1) )),0)/$N$1} -> 0 | T9: =Mappings!B8 -> 45705 | U9: {=IFERROR(ROWS(_xlfn._xlws.FILTER( DRG_Status!$A$2:$A$100000, (DRG_Status!$C$2:$C$100000=S_Curve_Data!T9) * (DRG_Status!$B$2:$B$100000=S_Curve_Data!$T$1) )),0)/$U$1} -> #N/A | V9: {=IFERROR(ROWS(_xlfn._xlws.FILTER( DRG_Status!$A$2:$A$100000, (DRG_Status!$D$2:$D$100000=S_Curve_Data!T9) * (DRG_Status!$B$2:$B$100000=S_Curve_Data!$T$1) )),0)/$U$1} -> #N/A | W9: {=IFERROR(ROWS(_xlfn._xlws.FILTER( DRG_Status!$A$2:$A$100000, (DRG_Status!$E$2:$E$100000=S_Curve_Data!T9) * (DRG_Status!$B$2:$B$100000=S_Curve_Data!$T$1) )),0)/$U$1} -> #N/A | X9: {=IFERROR(ROWS(_xlfn._xlws.FILTER( DRG_Status!$A$2:$A$100000, (DRG_Status!$F$2:$F$100000=S_Curve_Data!T9) * (DRG_Status!$B$2:$B$100000=S_Curve_Data!$T$1) )),0)/$U$1} -> #N/A | AA9: 45839 | AB9: {=IFERROR(ROWS(_xlfn._xlws.FILTER( DRG_Status!$A$2:$A$100000, (DRG_Status!$G$2:$G$100000=S_Curve_Data!AA9) * (DRG_Status!$B$2:$B$100000=S_Curve_Data!$AA$1) )),0)/$AB$1} -> 0 | AC9: {=IFERROR(ROWS(_xlfn._xlws.FILTER( DRG_Status!$A$2:$A$100000, (DRG_Status!$H$2:$H$100000=S_Curve_Data!AA9) * (DRG_Status!$B$2:$B$100000=S_Curve_Data!$AA$1) )),0)/$AB$1} -> 0 | AD9: {=IFERROR(ROWS(_xlfn._xlws.FILTER( DRG_Status!$A$2:$A$100000, (DRG_Status!$I$2:$I$100000=S_Curve_Data!AA9) * (DRG_Status!$B$2:$B$100000=S_Curve_Data!$AA$1) )),0)/$AB$1} -> 0 | AE9: {=IFERROR(ROWS(_xlfn._xlws.FILTER( DRG_Status!$A$2:$A$100000, (DRG_Status!$J$2:$J$100000=S_Curve_Data!AA9) * (DRG_Status!$B$2:$B$100000=S_Curve_Data!$AA$1) )),0)/$AB$1} -> 0 | AH9: 45839 | AI9: {=IFERROR(ROWS(_xlfn._xlws.FILTER( DRG_Status!$A$2:$A$100000, (DRG_Status!$G$2:$G$100000=S_Curve_Data!AH9) * (DRG_Status!$B$2:$B$100000=S_Curve_Data!$AH$1) )),0)/$AI$1} -> 0 | AJ9: {=IFERROR(ROWS(_xlfn._xlws.FILTER( DRG_Status!$A$2:$A$100000, (DRG_Status!$H$2:$H$100000=S_Curve_Data!AH9) * (DRG_Status!$B$2:$B$100000=S_Curve_Data!$AH$1) )),0)/$AI$1} -> 0 | AK9: {=IFERROR(ROWS(_xlfn._xlws.FILTER( DRG_Status!$A$2:$A$100000, (DRG_Status!$I$2:$I$100000=S_Curve_Data!AH9) * (DRG_Status!$B$2:$B$100000=S_Curve_Data!$AH$1) )),0)/$AI$1} -> 0 | AL9: {=IFERROR(ROWS(_xlfn._xlws.FILTER( DRG_Status!$A$2:$A$100000, (DRG_Status!$J$2:$J$100000=S_Curve_Data!AH9) * (DRG_Status!$B$2:$B$100000=S_Curve_Data!$AH$1) )),0)/$AI$1} -> 0 | AO9: 45839 | AP9: {=IFERROR(ROWS(_xlfn._xlws.FILTER( DRG_Status!$A$2:$A$100000, (DRG_Status!$G$2:$G$100000=S_Curve_Data!AO9) * (DRG_Status!$B$2:$B$100000=S_Curve_Data!$AO$1) )),0)/$AP$1} -> #N/A | AQ9: {=IFERROR(ROWS(_xlfn._xlws.FILTER( DRG_Status!$A$2:$A$100000, (DRG_Status!$H$2:$H$100000=S_Curve_Data!AO9) * (DRG_Status!$B$2:$B$100000=S_Curve_Data!$AO$1) )),0)/$AP$1} -> #N/A | AR9: {=IFERROR(ROWS(_xlfn._xlws.FILTER( DRG_Status!$A$2:$A$100000, (DRG_Status!$I$2:$I$100000=S_Curve_Data!AO9) * (DRG_Status!$B$2:$B$100000=S_Curve_Data!$AO$1) )),0)/$AP$1} -> #N/A | AS9: {=IFERROR(ROWS(_xlfn._xlws.FILTER( DRG_Status!$A$2:$A$100000, (DRG_Status!$J$2:$J$100000=S_Curve_Data!AO9) * (DRG_Status!$B$2:$B$100000=S_Curve_Data!$AO$1) )),0)/$AP$1} -> #N/A
