Workbook
Name NativeTimeline_Rpt_Month: #N/A
Name NativeTimeline_Rpt_Month1: #N/A
Name NativeTimeline_Rpt_Month2: #N/A
Name NativeTimeline_Rpt_Week: #N/A
Name NativeTimeline_Rpt_Week1: #N/A
Name NativeTimeline_Rpt_Week2: #N/A
Name Slicer_Discipline: #N/A
Name Slicer_Discipline1: #N/A

Sheet Floor-wise
A1: Row Labels | B1: Total Drgs | C1: Submitted | D1: Approved
A2: Above Roof | B2: 1 | C2: 1 | D2: 1
A3: Basement | B3: 8 | C3: 8 | D3: 8
A4: Common | B4: 12 | C4: 12 | D4: 11
A5: Detail Drawings | B5: 20 | C5: 19 | D5: 19
A6: Eighth Floor | B6: 11 | C6: 11 | D6: 11
A7: Existing Building | B7: 24 | C7: 18 | D7: 18
A8: External | B8: 5 | C8: 5 | D8: 5
A9: Fifth Floor | B9: 7 | C9: 7 | D9: 7
A10: First Floor | B10: 7 | C10: 7 | D10: 7
A11: Fourth Floor | B11: 7 | C11: 7 | D11: 7
A12: Ground Floor | B12: 7 | C12: 7 | D12: 7
A13: Ninth floor | B13: 10 | C13: 10 | D13: 10
... A22: Grand Total | B22: 183 | C22: 176 | D22: 175

Sheet S-Curve Wkly
BI9: Row Labels | BJ9: Submission_1 Plan | BK9: Submission_1 Actuals | BL9: Approval Plan | BM9: Approval Actuals
A10: Row Labels | B10: Submission_1 Plan | C10: Submission_1 Actuals | D10: Approval Plan | E10: Approval Actuals | AI10: Row Labels | AJ10: Submission_1 Plan | AK10: Submission_1 Actuals | AL10: Approval Plan | AM10: Approval Actuals | BI10: 45782 | BJ10: 0 | BK10: 0 | BL10: 0.0042372881 | BM10: 0
A11: 45719 | B11: 0.076502732 | C11: 0.081967213 | D11: 0 | E11: 0 | AI11: 45691 | AJ11: 0 | AK11: 0 | AL11: 0 | AM11: 0 | BI11: 45789 | BJ11: 0.063559322 | BK11: 0 | BL11: 0.0084745763 | BM11: 0
A12: 45726 | B12: 0.092896175 | C12: 0.10382514 | D12: 0 | E12: 0.021857923 | AI12: 45698 | AJ12: 0 | AK12: 0 | AL12: 0 | AM12: 0 | BI12: 45796 | BJ12: 0.063559322 | BK12: 0.059322034 | BL12: 0.0084745763 | BM12: 0
A13: 45733 | B13: 0.092896175 | C13: 0.10382514 | D13: 0 | E13: 0.021857923 | AI13: 45705 | AJ13: 0 | AK13: 0 | AL13: 0 | AM13: 0 | BI13: 45803 | BJ13: 0.11864407 | BK13: 0.059322034 | BL13: 0.11864407 | BM13: 0.080508475
A14: 45740 | B14: 0.1147541 | C14: 0.14754098 | D14: 0.071038251 | E14: 0.081967213 | AI14: 45712 | AJ14: 0 | AK14: 0 | AL14: 0 | AM14: 0 | BI14: 45810 | BJ14: 0.11864407 | BK14: 0.059322034 | BL14: 0.15254237 | BM14: 0.19915254
A15: 45747 | B15: 0.22404372 | C15: 0.20765027 | D15: 0.081967213 | E15: 0.081967213 | AI15: 45719 | AJ15: 0.13821138 | AK15: 0.13821138 | AL15: 0 | AM15: 0 | BI15: 45817 | BJ15: 0.18644068 | BK15: 0.059322034 | BL15: 0.19915254 | BM15: 0.19915254
A16: 45754 | B16: 0.2295082 | C16: 0.25136612 | D16: 0.10382514 | E16: 0.081967213 | AI16: 45726 | AJ16: 0.13821138 | AK16: 0.14634146 | AL16: 0 | AM16: 0 | BI16: 45824 | BJ16: 0.19915254 | BK16: 0.11440678 | BL16: 0.20762712 | BM16: 0.19915254
A17: 45761 | B17: 0.2295082 | C17: 0.2568306 | D17: 0.19125683 | E17: 0.081967213 | AI17: 45733 | AJ17: 0.13821138 | AK17: 0.14634146 | AL17: 0 | AM17: 0 | BI17: 45831 | BJ17: 0.31779661 | BK17: 0.11440678 | BL17: 0.22033898 | BM17: 0.19915254
A18: 45768 | B18: 0.2295082 | C18: 0.2568306 | D18: 0.21311475 | E18: 0.098360656 | AI18: 45740 | AJ18: 0.13821138 | AK18: 0.14634146 | AL18: 0.024390244 | AM18: 0.13821138 | BI18: 45838 | BJ18: 0.31779661 | BK18: 0.17372881 | BL18: 0.27542373 | BM18: 0.19915254
A19: 45775 | B19: 0.2295082 | C19: 0.26229508 | D19: 0.23497268 | E19: 0.098360656 | AI19: 45747 | AJ19: 0.17886179 | AK19: 0.17886179 | AL19: 0.13821138 | AM19: 0.13821138 | BI19: 45845 | BJ19: 0.40254237 | BK19: 0.23305085 | BL19: 0.27966102 | BM19: 0.25847458
A20: 45782 | B20: 0.2295082 | C20: 0.26229508 | D20: 0.24043716 | E20: 0.098360656 | AI20: 45754 | AJ20: 0.23577236 | AK20: 0.22764228 | AL20: 0.13821138 | AM20: 0.13821138 | BI20: 45852 | BJ20: 0.41525424 | BK20: 0.23305085 | BL20: 0.3940678 | BM20: 0.25847458
A21: 45789 | B21: 0.26775956 | C21: 0.26229508 | D21: 0.24043716 | E21: 0.10382514 | AI21: 45761 | AJ21: 0.25203252 | AK21: 0.2601626 | AL21: 0.13821138 | AM21: 0.13821138 | BI21: 45859 | BJ21: 0.4279661 | BK21: 0.24152542 | BL21: 0.3940678 | BM21: 0.25847458
A22: 45796 | B22: 0.26775956 | C22: 0.27322404 | D22: 0.24043716 | E22: 0.10382514 | AI22: 45768 | AJ22: 0.25203252 | AK22: 0.2601626 | AL22: 0.13821138 | AM22: 0.13821138 | BI22: 45866 | BJ22: 0.4279661 | BK22: 0.24152542 | BL22: 0.50423729 | BM22: 0.25847458
... A61: 46069 | B61: 0.93442623 | C61: 0.93442623 | D61: 0.86885246 | E61: 0.84153005 | AI61: 46041 | AJ61: 1 | AK61: 0.94308943 | AL61: 0.98373984 | AM61: 0.89430894 | BI61: 46139 | BJ61: 0.68644068 | BK61: 0.75847458 | BL61: 0.80084746 | BM61: 0.89830508
A62: 46076 | B62: 1 | C62: 0.93442623 | D62: 0.86885246 | E62: 0.84153005 | AI62: 46048 | AJ62: 1 | AK62: 0.94308943 | AL62: 1 | AM62: 0.89430894 | BI62: Grand Total
A63: Grand Total | AI63: 46055 | AJ63: 1 | AK63: 0.94308943 | AL63: 1 | AM63: 0.89430894
AI64: 46062 | AJ64: 1 | AK64: 0.94308943 | AL64: 1 | AM64: 0.89430894
AI65: 46069 | AJ65: 1 | AK65: 0.94308943 | AL65: 1 | AM65: 0.89430894
AI66: 46076 | AJ66: 1 | AK66: 0.94308943 | AL66: 1 | AM66: 0.89430894
AI67: 46083 | AJ67: 1 | AK67: 0.96747967 | AL67: 1 | AM67: 0.89430894
AI68: 46090 | AJ68: 1 | AK68: 0.99186992 | AL68: 1 | AM68: 0.89430894
AI69: 46097 | AJ69: 1 | AK69: 0.99186992 | AL69: 1 | AM69: 0.89430894
AI70: 46104 | AJ70: 1 | AK70: 0.99186992 | AL70: 1 | AM70: 0.89430894
AI71: 46111 | AJ71: 1 | AK71: 0.99186992 | AL71: 1 | AM71: 0.89430894
AI72: 46118 | AJ72: 1 | AK72: 1 | AL72: 1 | AM72: 0.89430894
AI73: 46125 | AJ73: 1 | AK73: 1 | AL73: 1 | AM73: 0.89430894
AI74: 46132 | AJ74: 1 | AK74: 1 | AL74: 1 | AM74: 0.98373984
AI75: 46139 | AJ75: 1 | AK75: 1 | AL75: 1 | AM75: 0.98373984
... AI79: 46167 | AJ79: 1 | AK79: 1 | AL79: 1 | AM79: 1
AI80: Grand Total

Sheet S-Curve Monthly
A1: Row Labels | B1: Submission_1 Plan | C1: Submission_1 Actuals | D1: Approval Plan | E1: Approval Actuals | AA1: Row Labels | AB1: Submission_1 Plan | AC1: Submission_1 Actuals | AD1: Approval Plan | AE1: Approval Actuals | BA1: Row Labels | BB1: Submission_1 Plan | BC1: Submission_1 Actuals | BD1: Approval Plan | BE1: Approval Actuals
A2: 45689 | B2: 0 | C2: 0 | D2: 0 | E2: 0 | AA2: 45717 | AB2: 0.13821138 | AC2: 0.14634146 | AD2: 0.13821138 | AE2: 0.13821138 | BA2: 45689 | BB2: 0 | BC2: 0 | BD2: 0 | BE2: 0
A3: 45717 | B3: 0.20218579 | C3: 0.14754098 | D3: 0.081967213 | E3: 0.081967213 | AA3: 45748 | AB3: 0.25203252 | AC3: 0.2601626 | AD3: 0.13821138 | AE3: 0.13821138 | BA3: 45717 | BB3: 0.30084746 | BC3: 0.093220339 | BD3: 0 | BE3: 0.0042372881
A4: 45748 | B4: 0.2295082 | C4: 0.2568306 | D4: 0.21311475 | E4: 0.098360656 | AA4: 45778 | AB4: 0.41463415 | AC4: 0.32520325 | AD4: 0.25203252 | AE4: 0.15447154 | BA4: 45748 | BB4: 0.31355932 | BC4: 0.24152542 | BD4: 0.19915254 | BE4: 0.046610169
A5: 45778 | B5: 0.31693989 | C5: 0.27322404 | D5: 0.24043716 | E5: 0.15300546 | AA5: 45809 | AB5: 0.43902439 | AC5: 0.42276423 | AD5: 0.41463415 | AE5: 0.15447154 | BA5: 45778 | BB5: 0.43220339 | BC5: 0.30084746 | BD5: 0.26694915 | BE5: 0.12711864
A6: 45809 | B6: 0.45901639 | C6: 0.3442623 | D6: 0.32786885 | E6: 0.2295082 | AA6: 45839 | AB6: 0.43902439 | AC6: 0.45528455 | AD6: 0.43902439 | AE6: 0.2195122 | BA6: 45809 | BB6: 0.63135593 | BC6: 0.3559322 | BD6: 0.41949153 | BE6: 0.24576271
A7: 45839 | B7: 0.57377049 | C7: 0.45355191 | D7: 0.47540984 | E7: 0.27322404 | AA7: 45870 | AB7: 0.44715447 | AC7: 0.47154472 | AD7: 0.44715447 | AE7: 0.23577236 | BA7: 45839 | BB7: 0.74152542 | BC7: 0.48305085 | BD7: 0.59322034 | BE7: 0.30508475
A8: 45870 | B8: 0.57377049 | C8: 0.56284153 | D8: 0.60655738 | E8: 0.30601093 | AA8: 45901 | AB8: 0.44715447 | AC8: 0.47154472 | AD8: 0.44715447 | AE8: 0.41463415 | BA8: 45870 | BB8: 0.74152542 | BC8: 0.61440678 | BD8: 0.80932203 | BE8: 0.31779661
A9: 45901 | B9: 0.57377049 | C9: 0.6010929 | D9: 0.60655738 | E9: 0.36612022 | AA9: 45931 | AB9: 0.49593496 | AC9: 0.53658537 | AD9: 0.44715447 | AE9: 0.45528455 | BA9: 45901 | BB9: 0.74152542 | BC9: 0.66949153 | BD9: 0.80932203 | BE9: 0.31779661
A10: 45931 | B10: 0.6557377 | C10: 0.65027322 | D10: 0.61748634 | E10: 0.52459016 | AA10: 45962 | AB10: 0.6504065 | AC10: 0.72357724 | AD10: 0.55284553 | AE10: 0.49593496 | BA10: 45931 | BB10: 0.86016949 | BC10: 0.73728814 | BD10: 0.80932203 | BE10: 0.61440678
A11: 45962 | B11: 0.7431694 | C11: 0.75409836 | D11: 0.73770492 | E11: 0.52459016 | AA11: 45992 | AB11: 1 | AC11: 0.92682927 | AD11: 0.75609756 | AE11: 0.86178862 | BA11: 45962 | BB11: 0.97881356 | BC11: 0.97033898 | BD11: 0.98305085 | BE11: 0.61440678
A12: 45992 | B12: 0.86885246 | C12: 0.82513661 | D12: 0.75956284 | E12: 0.75409836 | AA12: 46023 | AB12: 1 | AC12: 0.94308943 | AD12: 1 | AE12: 0.89430894 | BA12: 45992 | BB12: 1 | BC12: 0.97033898 | BD12: 0.99152542 | BE12: 0.78813559
A13: 46023 | B13: 0.86885246 | C13: 0.8579235 | D13: 0.86885246 | E13: 0.75956284 | AA13: Grand Total | BA13: Grand Total
A14: 46054 | B14: 1 | C14: 0.93442623 | D14: 0.86885246 | E14: 0.84153005
A15: 46082 | B15: 1 | C15: 0.94535519 | D15: 1 | E15: 0.84153005
A16: Grand Total

Sheet DB
A1: Row Labels | B1: Count of DRG ID
A2: Architecture | B2: 123
A3: MEP | B3: 236
A4: Structural | B4: 183
A5: Grand Total | B5: 542
A24: Row Labels | B24: Count of DRG ID | C24: Count of Actual Submission to Client | D24: Count of Actual Approval Date | F24: Discipline | G24: Submission Status | H24: Approval Status
A25: Architecture | B25: 123 | C25: 123 | D25: 123 | F25: =A25 -> Architecture | G25: =GETPIVOTDATA("Count of Actual Submission to Client",$A$24,"Discipline","Architecture")/GETPIVOTDATA("Count of DRG ID",$A$24,"Discipline","Architecture") -> 1 | H25: =GETPIVOTDATA("Count of Actual Approval Date",$A$24,"Discipline","Architecture")/GETPIVOTDATA("Count of DRG ID",$A$24,"Discipline","Architecture") -> 1
A26: MEP | B26: 236 | C26: 236 | D26: 223 | F26: =A26 -> MEP | G26: =GETPIVOTDATA("Count of Actual Submission to Client",$A$24,"Discipline","MEP")/GETPIVOTDATA("Count of DRG ID",$A$24,"Discipline","MEP") -> 1 | H26: =GETPIVOTDATA("Count of Actual Approval Date",$A$24,"Discipline","MEP")/GETPIVOTDATA("Count of DRG ID",$A$24,"Discipline","MEP") -> 0.94491525
A27: Structural | B27: 183 | C27: 176 | D27: 175 | F27: =A27 -> Structural | G27: =GETPIVOTDATA("Count of Actual Submission to Client",$A$24,"Discipline","Structural")/GETPIVOTDATA("Count of DRG ID",$A$24,"Discipline","Structural") -> 0.96174863 | H27: =GETPIVOTDATA("Count of Actual Approval Date",$A$24,"Discipline","Structural")/GETPIVOTDATA("Count of DRG ID",$A$24,"Discipline","Structural") -> 0.95628415
A28: Grand Total | B28: 542 | C28: 535 | D28: 521
A39: Speedometer | B39: Value | C39: Pointer | D39: Value
A40: Start | B40: 0 | C40: Value | D40: =H27*100 -> 95.628415
A41: Initial | B41: 30 | C41: Pointer | D41: 2
A42: Mid | B42: 40 | C42: End | D42: =SUM(B40:B44)-SUM(D40:D41) -> 102.37158
A43: End | B43: 30
A44: Max | B44: 100
A69: Discipline | B69: (All)
A71: Row Labels | B71: Total DRG ID | C71: Submitted | D71: Approved
A72: Electrical | B72: 79 | C72: 79 | D72: 76
A73: ELV | B73: 65 | C73: 65 | D73: 56
A74: Existing Building | B74: 24 | C74: 18 | D74: 18
A75: Fire | B75: 46 | C75: 46 | D75: 46
A76: HVAC | B76: 76 | C76: 76 | D76: 75
A77: MEP | B77: 26 | C77: 26 | D77: 26
A78: New Building | B78: 180 | C78: 179 | D78: 179
A79: PHE | B79: 46 | C79: 46 | D79: 45
A80: Grand Total | B80: 542 | C80: 535 | D80: 521

Sheet Master_Data
A1: S.no | B1: Discipline | C1: Category | D1: DRG ID | E1: Description | F1: MDL Title | G1: Responsible Person | H1: 1st Submission Plan | I1: 1st Submission Plan (Before changes in scope) | J1: Actual Submission to Client | K1: Revised Submission date (Plan) | L1: Actual Revised submission | M1: Planned Approval Date | N1: Actual Approval Date | O1: Planned Hard copy Sub.dates | P1: Actual Hard copy sub.dates | Q1: Dependency
A2: 1 | B2: MEP | C2: PHE | D2: WLH/KEC/SIEC/SEWAGE/BASEMENT/00 | E2: Basement | F2: PHE BASEMENT SEWARAGE FLOOR PLAN | G2: Aashish | H2: 45747 | I2: 45747 | J2: 45751 | K2: 45759 | L2: 45751 | M2: 45766 | N2: 45808 | O2: 45773
A3: 2 | B3: MEP | C3: PHE | D3: WLH/KEC/SIEC/DRAINAGE/BASEMENT/00 | E3: Basement | F3: SANITARY & DRAINAGE BASEMENT CIELING PLAN | G3: Aashish | H3: 45747 | I3: 45747 | J3: 45751 | K3: 45759 | L3: 45751 | M3: 45766 | N3: 45808 | O3: 45773
A4: 3 | B4: MEP | C4: PHE | D4: WLH/KEC/SIEC/WATER SUPPLY/GF FL/00 | E4: Ground Floor | F4: PHE WATER SUPPLY GROUND FLOOR PLAN | G4: Aashish | H4: 45747 | I4: 45747 | J4: 45754 | K4: 45759 | L4: 45805 | M4: 45766 | N4: 45812 | O4: 45773
A5: 4 | B5: MEP | C5: PHE | D5: WLH/KEC/SIEC/DRAINAGE/GF FL/00 | E5: Ground Floor | F5: SANITARY & DRAINAGE GROUND CIELING PLAN | G5: Aashish | H5: 45747 | I5: 45747 | J5: 45754 | K5: 45759 | L5: 45805 | M5: 45766 | N5: 45812 | O5: 45773
A6: 5 | B6: MEP | C6: PHE | D6: WLH/KEC/SIEC/WATER SUPPLY/1ST FL/00 | E6: First Floor | F6: PHE WATER SUPPLY 1ST FLOOR PLAN | G6: Aashish | H6: 45976 | I6: 45747 | J6: 45974 | K6: 45759 | L6: 45796 | M6: 45990 | N6: 45995 | O6: 45997
A7: 6 | B7: MEP | C7: PHE | D7: WLH/KEC/SIEC/DRAINAGE/1ST FL/00 | E7: First Floor | F7: SANITARY & DRAINAGE 1ST CIELING PLAN | G7: Aashish | H7: 45976 | I7: 45747 | J7: 45974 | K7: 45759 | L7: 45796 | M7: 45990 | N7: 45995 | O7: 45997
A8: 7 | B8: MEP | C8: PHE | D8: WLH/KEC/SIEC/WATER SUPPLY/2ND FL/00 | E8: Second Floor | F8: PHE WATER SUPPLY 2ND FLOOR PLAN | G8: Aashish | H8: 45960 | I8: 45760 | J8: 45966 | K8: 45772 | L8: 45751 | M8: 45974 | N8: 45995 | O8: 45981
A9: 8 | B9: MEP | C9: PHE | D9: WLH/KEC/SIEC/DRAINAGE/2ND FL/00 | E9: Second Floor | F9: SANITARY & DRAINAGE 2ND CIELING PLAN | G9: Aashish | H9: 45960 | I9: 45760 | J9: 45966 | K9: 45772 | L9: 45751 | M9: 45974 | N9: 45995 | O9: 45981
A10: 9 | B10: MEP | C10: PHE | D10: WLH/KEC/SIEC/WATER SUPPLY/3RD FL/00 | E10: Third Floor | F10: PHE WATER SUPPLY 3RD FLOOR PLAN | G10: Aashish | H10: 45955 | I10: 45776 | J10: 45958 | K10: 45788 | L10: 45889 | M10: 45969 | N10: 45995 | O10: 45976
A11: 10 | B11: MEP | C11: PHE | D11: WLH/KEC/SIEC/DRAINAGE/3RD FL/00 | E11: Third Floor | F11: SANITARY & DRAINAGE 3RD CIELING PLAN | G11: Aashish | H11: 45955 | I11: 45776 | J11: 45958 | K11: 45788 | L11: 45889 | M11: 45969 | N11: 45995 | O11: 45976
A12: 11 | B12: MEP | C12: PHE | D12: WLH/KEC/SIEC/WATER SUPPLY/4TH FL/00 | E12: Fourth Floor | F12: PHE WATER SUPPLY 4TH FLOOR PLAN | G12: Aashish | H12: 45790 | I12: 45790 | J12: 45796 | K12: 45802 | L12: 45751 | M12: 45804 | N12: 45812 | O12: 45811
A13: 12 | B13: MEP | C13: PHE | D13: WLH/KEC/SIEC/DRAINAGE/4TH FL/00 | E13: Fourth Floor | F13: SANITARY & DRAINAGE 4TH CIELING PLAN | G13: Aashish | H13: 45790 | I13: 45790 | J13: 45796 | K13: 45802 | L13: 45751 | M13: 45809 | N13: 45812 | O13: 45816
... A17: 16 | B17: MEP | C17: PHE | D17: WLH/KEC/SIEC/DRAINAGE/6TH FL/00 | E17: Sixth Floor | F17: SANITARY & DRAINAGE 6TH CIELING PLAN | G17: Aashish | H17: 45821 | I17: 45821 | J17: 45847 | K17: 45833 | L17: 45883 | M17: 45840 | N17: 45946 | O17: 45847
A18: 17 | B18: MEP | C18: PHE | D18: WLH/KEC/SIEC/WATER SUPPLY/7TH FL/00 | E18: Seventh Floor | F18: PHE WATER SUPPLY 7TH FLOOR PLAN | G18: Aashish | H18: 45837 | I18: 45837 | J18: 45896 | K18: 45849 | M18: 45856 | N18: 45946 | O18: 45863
A19: 18 | B19: MEP | C19: PHE | D19: WLH/KEC/SIEC/DRAINAGE/7TH FL/00 | E19: Seventh Floor | F19: SANITARY & DRAINAGE 7TH CIELING PLAN | G19: Aashish | H19: 45837 | I19: 45837 | J19: 45896 | K19: 45849 | M19: 45856 | N19: 45946 | O19: 45863
A20: 19 | B20: MEP | C20: PHE | D20: WLH/KEC/SIEC/WATER SUPPLY/8TH FL/00 | E20: Eighth Floor | F20: GFC PHE WATER SUPPLY 8TH FLOOR PLAN | G20: Aashish | H20: 45837 | I20: 45837 | J20: 45899 | K20: 45849 | M20: 45856 | N20: 45959 | O20: 45863
A21: 20 | B21: MEP | C21: PHE | D21: WLH/KEC/SIEC/DRAINAGE/8TH FL/00 | E21: Eighth Floor | F21: SANITARY & DRAINAGE 8TH CIELING PLAN | G21: Aashish | H21: 45837 | I21: 45837 | J21: 45899 | K21: 45849 | M21: 45856 | N21: 45959 | O21: 45863
A22: 21 | B22: MEP | C22: PHE | D22: WLH/KEC/SIEC/WATER SUPPLY/9TH FL/00 | E22: Ninth floor | F22: PHE WATER SUPPLY 9th FLOOR PLAN | G22: Aashish | H22: 45851 | I22: 45851 | J22: 45826 | K22: 45863 | M22: 45870 | N22: 45850 | O22: 45877
A23: 22 | B23: MEP | C23: PHE | D23: WLH/KEC/SIEC/DRAINAGE/9TH FL/00 | E23: Ninth floor | F23: SANITARY & DRAINAGE 9th CIELING PLAN | G23: Aashish | H23: 45851 | I23: 45851 | J23: 45826 | K23: 45863 | M23: 45870 | N23: 45850 | O23: 45877
A24: 23 | B24: MEP | C24: PHE | D24: WLH/KEC/SIEC/WATER SUPPLY/10TH FL/00 | E24: Tenth Floor | F24: PHE WATER SUPPLY 10th FLOOR PLAN | G24: Aashish | H24: 45851 | I24: 45851 | J24: 45910 | K24: 45863 | M24: 45870 | N24: 45946 | O24: 45877
A25: 24 | B25: MEP | C25: PHE | D25: WLH/KEC/SIEC/DRAINAGE/10TH FL/00 | E25: Tenth Floor | F25: SANITARY & DRAINAGE 10th CIELING PLAN | G25: Aashish | H25: 45851 | I25: 45851 | J25: 45910 | K25: 45863 | M25: 45870 | N25: 45946 | O25: 45877
A26: 25 | B26: MEP | C26: PHE | D26: WLH/KEC/SIEC/WATER SUPPLY/TERRACE FL/00 | E26: Terrace floor | F26: PHE WATER SUPPLY TERRACE PLAN | G26: Aashish | H26: 45976 | I26: 45866 | J26: 45974 | K26: 45878 | M26: 45885 | N26: 46071 | O26: 45892
A27: 26 | B27: MEP | C27: PHE | D27: WLH/KEC/SIEC/DRAINAGE/TRRRACE FL/00 | E27: Terrace floor | F27: SANITARY & DRAINAGE TERRACE PLAN | G27: Aashish | H27: 45976 | I27: 45866 | J27: 45974 | K27: 45878 | M27: 45885 | N27: 46071 | O27: 45892
A28: 27 | B28: MEP | C28: PHE | D28: WLH/KEC/SIEC/DRAINAGE/MUMTY TERRACE FL/00 | E28: Terrace floor | F28: SANITARY & DRAINAGE MUMTY TERRACE PLAN | G28: Aashish | H28: 45976 | I28: 45866 | J28: 45986 | K28: 45878 | M28: 45885 | N28: 46071 | O28: 45892
A29: 28 | B29: MEP | C29: PHE | D29: WLH/KEC/SIEC/PHE/INFRA/EXTSEWERAGE/00 | E29: External | F29: PHE EXTERNAL SEWERAGE LAYOUT | G29: Aashish | H29: 45731 | I29: 45731 | J29: 45966 | K29: 45799 | L29: 45902 | M29: 45806 | N29: 46071 | O29: 45813
A30: 29 | B30: MEP | C30: PHE | D30: WLH/KEC/SIEC/PHE/INFRA/00 | E30: External | F30: PHE EXTERNAL CO-ORDINATED LAYOUT | G30: Aashish | H30: 45731 | I30: 45731 | J30: 45966 | K30: 45799 | L30: 45902 | M30: 45806 | N30: 46071 | O30: 45813
A31: 30 | B31: MEP | C31: PHE | D31: WLH/KEC/SIEC/PHE/INFRA WATER SUPPLY/00 | E31: External | F31: PHE INFRASTRUCTURE WATER SUPPLY LAYOUT | G31: Aashish | H31: 45731 | I31: 45731 | J31: 45966 | K31: 45799 | L31: 45902 | M31: 45806 | N31: 46071 | O31: 45813
A32: 31 | B32: MEP | C32: PHE | D32: WLH/KEC/SIEC/PHE/INFRA/EXTSTORMWATER/00 | E32: External | F32: PHE EXTERNAL STORM WATER LAYOUT | G32: Aashish | H32: 45731 | I32: 45731 | J32: 45966 | K32: 45799 | L32: 45902 | M32: 45806 | N32: 46071 | O32: 45813
A33: 32 | B33: MEP | C33: PHE | D33: WLH/KEC/SIEC/PHE/INFRA/RECHARGE BOREWELL00 | E33: External | F33: PHE EXTERNAL RECHARGE BOREWELL DRAWING | G33: Aashish | H33: 45731 | I33: 45731 | J33: 45966 | K33: 45799 | L33: 45902 | M33: 45806 | N33: 46071 | O33: 45813
A34: 33 | B34: MEP | C34: PHE | D34: WLH/KEC/SIEC/WATER SUPPLY SLD/00 | E34: Common | F34: WATER SUPPLY SINGLE LINE DIAGRAM | G34: Aashish | H34: 45731 | I34: 45731 | J34: 45731 | K34: 45799 | L34: 45902 | M34: 45806 | N34: 46080 | O34: 45813
A35: 34 | B35: MEP | C35: PHE | D35: WLH/KEC/SIEC/SANITARY DRAINAGE/SLD/00 | E35: Common | F35: SANITARY DRAINAGE SINGLE LINE DIAGRAM | G35: Aashish | H35: 45826 | I35: 45826 | J35: 45898 | K35: 45799 | M35: 45833 | N35: 45898 | O35: 45840
A36: 35 | B36: MEP | C36: PHE | D36: WLH/KEC/SIEC/RAIN WATER DRAINAGE/SLD/00 | E36: Common | F36: RAINWATER DRAINAGE SINGLE LINE DIAGRAM | G36: Aashish | H36: 45826 | I36: 45826 | J36: 45898 | K36: 45799 | M36: 45833 | N36: 45898 | O36: 45840
A37: 36 | B37: MEP | C37: PHE | D37: WLH/KEC/SIEC/OWT/PHE/00 | E37: Common | F37: OVERHEAD WATER TANK & EQUIPMENT ROOM DETAILS | G37: Aashish | H37: 45826 | I37: #REF! | J37: 45986 | K37: #REF! | M37: 45833 | O37: 45840
A38: 37 | B38: MEP | C38: PHE | D38: WLH/KEC/SIEC/DRAINAGE/BASEMENT/DEWATERING/00 | E38: Basement | F38: BASEMENT DEWATERING LAYOUT | G38: Aashish | H38: 45731 | I38: 45731 | J38: 45731 | K38: 45799 | M38: 45806 | N38: 45808 | O38: 45813
A39: 38 | B39: MEP | C39: PHE | D39: WLH/KEC/SIEC/PHE/CONST. DETAILS/00 | E39: Common | F39: PHE TYPICAL STANDARD CONSTRUCTION DETAILS | G39: Aashish | H39: 45731 | I39: 45731 | J39: 45898 | K39: 45799 | M39: 45806 | N39: 45898 | O39: 45813
A40: 39 | B40: MEP | C40: PHE | D40: WLH/KEC/SIEC/WATER SUPPLY/EXTERNAL/00 | E40: Common | F40: PHE WATER SUPPLY EXTERNAL LAYOUT | G40: Aashish | H40: 45731 | I40: 45731 | J40: 45731 | K40: 45799 | L40: 45902 | M40: 45806 | N40: 46071 | O40: 45813
A41: 40 | B41: MEP | C41: PHE | D41: WLH/KEC/SIEC/PHE/BASEMENT TOILET/00 | E41: Basement | F41: PHE BASEMENT TOILET SEWAGE LAYOUT | G41: Aashish | H41: 45731 | I41: 45731 | J41: 45731 | K41: 45799 | M41: 45806 | N41: 45808 | O41: 45813
A42: 41 | B42: MEP | C42: PHE | D42: WLH/KEC/SIEC/DRAINAGE/SUMP DETAIL/00 | E42: Common | F42: PHE SUMP DETAILS LAYOUT | G42: Aashish | H42: 45731 | I42: 45731 | J42: 45731 | K42: 45799 | M42: 45806 | N42: 45808 | O42: 45813
A43: 42 | B43: MEP | C43: PHE | D43: WLH/KEC/STP/BASEMENT/00 | E43: Common | F43: STP DESIGN DRAWINGS | G43: Aashish | H43: 45731 | I43: 45731 | J43: 45731 | K43: 45748 | L43: 45731 | M43: 45761 | N43: 45761 | O43: 45768
...

Sheet DRG_Status
A1: DRG ID | B1: Discipline | C1: 1st Submission Plan_wk | D1: Actual Submission to Client_wk | E1: Planned Approval_wk | F1: Actual Approval_wk | G1: 1st Submission Plan_mth | H1: Actual Submission to Client_mth | I1: Planned Approval_mth | J1: Actual Approval_mth
A2: =Master_Data!D2 -> WLH/KEC/SIEC/SEWAGE/BASEMENT/00 | B2: =Master_Data!B2 -> MEP | C2: =IF(Master_Data!H2="","",Master_Data!H2 - WEEKDAY(Master_Data!H2,2) + 1) -> 45747 | D2: =IF(Master_Data!J2="","",Master_Data!J2 - WEEKDAY(Master_Data!J2,2) + 1) -> 45747 | E2: =IF(Master_Data!M2="","",Master_Data!M2 - WEEKDAY(Master_Data!M2,2) + 1) -> 45761 | F2: =IF(Master_Data!N2="","",Master_Data!N2 - WEEKDAY(Master_Data!N2,2) + 1) -> 45803 | G2: =EOMONTH(Master_Data!H2,-1)+1 -> 45717 | H2: =IF(Master_Data!J2="","",EOMONTH(Master_Data!J2,-1)+1) -> 45748 | I2: =IF(Master_Data!M2="","",EOMONTH(Master_Data!M2,-1)+1) -> 45748 | J2: =IF(Master_Data!N2="","",EOMONTH(Master_Data!N2,-1)+1) -> 45778
A3: =Master_Data!D3 -> WLH/KEC/SIEC/DRAINAGE/BASEMENT/00 | B3: =Master_Data!B3 -> MEP | C3: =IF(Master_Data!H3="","",Master_Data!H3 - WEEKDAY(Master_Data!H3,2) + 1) -> 45747 | D3: =IF(Master_Data!J3="","",Master_Data!J3 - WEEKDAY(Master_Data!J3,2) + 1) -> 45747 | E3: =IF(Master_Data!M3="","",Master_Data!M3 - WEEKDAY(Master_Data!M3,2) + 1) -> 45761 | F3: =IF(Master_Data!N3="","",Master_Data!N3 - WEEKDAY(Master_Data!N3,2) + 1) -> 45803 | G3: =EOMONTH(Master_Data!H3,-1)+1 -> 45717 | H3: =IF(Master_Data!J3="","",EOMONTH(Master_Data!J3,-1)+1) -> 45748 | I3: =IF(Master_Data!M3="","",EOMONTH(Master_Data!M3,-1)+1) -> 45748 | J3: =IF(Master_Data!N3="","",EOMONTH(Master_Data!N3,-1)+1) -> 45778
A4: =Master_Data!D4 -> WLH/KEC/SIEC/WATER SUPPLY/GF FL/00 | B4: =Master_Data!B4 -> MEP | C4: =IF(Master_Data!H4="","",Master_Data!H4 - WEEKDAY(Master_Data!H4,2) + 1) -> 45747 | D4: =IF(Master_Data!J4="","",Master_Data!J4 - WEEKDAY(Master_Data!J4,2) + 1) -> 45754 | E4: =IF(Master_Data!M4="","",Master_Data!M4 - WEEKDAY(Master_Data!M4,2) + 1) -> 45761 | F4: =IF(Master_Data!N4="","",Master_Data!N4 - WEEKDAY(Master_Data!N4,2) + 1) -> 45810 | G4: =EOMONTH(Master_Data!H4,-1)+1 -> 45717 | H4: =IF(Master_Data!J4="","",EOMONTH(Master_Data!J4,-1)+1) -> 45748 | I4: =IF(Master_Data!M4="","",EOMONTH(Master_Data!M4,-1)+1) -> 45748 | J4: =IF(Master_Data!N4="","",EOMONTH(Master_Data!N4,-1)+1) -> 45809
A5: =Master_Data!D5 -> WLH/KEC/SIEC/DRAINAGE/GF FL/00 | B5: =Master_Data!B5 -> MEP | C5: =IF(Master_Data!H5="","",Master_Data!H5 - WEEKDAY(Master_Data!H5,2) + 1) -> 45747 | D5: =IF(Master_Data!J5="","",Master_Data!J5 - WEEKDAY(Master_Data!J5,2) + 1) -> 45754 | E5: =IF(Master_Data!M5="","",Master_Data!M5 - WEEKDAY(Master_Data!M5,2) + 1) -> 45761 | F5: =IF(Master_Data!N5="","",Master_Data!N5 - WEEKDAY(Master_Data!N5,2) + 1) -> 45810 | G5: =EOMONTH(Master_Data!H5,-1)+1 -> 45717 | H5: =IF(Master_Data!J5="","",EOMONTH(Master_Data!J5,-1)+1) -> 45748 | I5: =IF(Master_Data!M5="","",EOMONTH(Master_Data!M5,-1)+1) -> 45748 | J5: =IF(Master_Data!N5="","",EOMONTH(Master_Data!N5,-1)+1) -> 45809
A6: =Master_Data!D6 -> WLH/KEC/SIEC/WATER SUPPLY/1ST FL/00 | B6: =Master_Data!B6 -> MEP | C6: =IF(Master_Data!H6="","",Master_Data!H6 - WEEKDAY(Master_Data!H6,2) + 1) -> 45971 | D6: =IF(Master_Data!J6="","",Master_Data!J6 - WEEKDAY(Master_Data!J6,2) + 1) -> 45971 | E6: =IF(Master_Data!M6="","",Master_Data!M6 - WEEKDAY(Master_Data!M6,2) + 1) -> 45985 | F6: =IF(Master_Data!N6="","",Master_Data!N6 - WEEKDAY(Master_Data!N6,2) + 1) -> 45992 | G6: =EOMONTH(Master_Data!H6,-1)+1 -> 45962 | H6: =IF(Master_Data!J6="","",EOMONTH(Master_Data!J6,-1)+1) -> 45962 | I6: =IF(Master_Data!M6="","",EOMONTH(Master_Data!M6,-1)+1) -> 45962 | J6: =IF(Master_Data!N6="","",EOMONTH(Master_Data!N6,-1)+1) -> 45992
A7: =Master_Data!D7 -> WLH/KEC/SIEC/DRAINAGE/1ST FL/00 | B7: =Master_Data!B7 -> MEP | C7: =IF(Master_Data!H7="","",Master_Data!H7 - WEEKDAY(Master_Data!H7,2) + 1) -> 45971 | D7: =IF(Master_Data!J7="","",Master_Data!J7 - WEEKDAY(Master_Data!J7,2) + 1) -> 45971 | E7: =IF(Master_Data!M7="","",Master_Data!M7 - WEEKDAY(Master_Data!M7,2) + 1) -> 45985 | F7: =IF(Master_Data!N7="","",Master_Data!N7 - WEEKDAY(Master_Data!N7,2) + 1) -> 45992 | G7: =EOMONTH(Master_Data!H7,-1)+1 -> 45962 | H7: =IF(Master_Data!J7="","",EOMONTH(Master_Data!J7,-1)+1) -> 45962 | I7: =IF(Master_Data!M7="","",EOMONTH(Master_Data!M7,-1)+1) -> 45962 | J7: =IF(Master_Data!N7="","",EOMONTH(Master_Data!N7,-1)+1) -> 45992
A8: =Master_Data!D8 -> WLH/KEC/SIEC/WATER SUPPLY/2ND FL/00 | B8: =Master_Data!B8 -> MEP | C8: =IF(Master_Data!H8="","",Master_Data!H8 - WEEKDAY(Master_Data!H8,2) + 1) -> 45957 | D8: =IF(Master_Data!J8="","",Master_Data!J8 - WEEKDAY(Master_Data!J8,2) + 1) -> 45964 | E8: =IF(Master_Data!M8="","",Master_Data!M8 - WEEKDAY(Master_Data!M8,2) + 1) -> 45971 | F8: =IF(Master_Data!N8="","",Master_Data!N8 - WEEKDAY(Master_Data!N8,2) + 1) -> 45992 | G8: =EOMONTH(Master_Data!H8,-1)+1 -> 45931 | H8: =IF(Master_Data!J8="","",EOMONTH(Master_Data!J8,-1)+1) -> 45962 | I8: =IF(Master_Data!M8="","",EOMONTH(Master_Data!M8,-1)+1) -> 45962 | J8: =IF(Master_Data!N8="","",EOMONTH(Master_Data!N8,-1)+1) -> 45992
A9: =Master_Data!D9 -> WLH/KEC/SIEC/DRAINAGE/2ND FL/00 | B9: =Master_Data!B9 -> MEP | C9: =IF(Master_Data!H9="","",Master_Data!H9 - WEEKDAY(Master_Data!H9,2) + 1) -> 45957 | D9: =IF(Master_Data!J9="","",Master_Data!J9 - WEEKDAY(Master_Data!J9,2) + 1) -> 45964 | E9: =IF(Master_Data!M9="","",Master_Data!M9 - WEEKDAY(Master_Data!M9,2) + 1) -> 45971 | F9: =IF(Master_Data!N9="","",Master_Data!N9 - WEEKDAY(Master_Data!N9,2) + 1) -> 45992 | G9: =EOMONTH(Master_Data!H9,-1)+1 -> 45931 | H9: =IF(Master_Data!J9="","",EOMONTH(Master_Data!J9,-1)+1) -> 45962 | I9: =IF(Master_Data!M9="","",EOMONTH(Master_Data!M9,-1)+1) -> 45962 | J9: =IF(Master_Data!N9="","",EOMONTH(Master_Data!N9,-1)+1) -> 45992
A10: =Master_Data!D10 -> WLH/KEC/SIEC/WATER SUPPLY/3RD FL/00 | B10: =Master_Data!B10 -> MEP | C10: =IF(Master_Data!H10="","",Master_Data!H10 - WEEKDAY(Master_Data!H10,2) + 1) -> 45950 | D10: =IF(Master_Data!J10="","",Master_Data!J10 - WEEKDAY(Master_Data!J10,2) + 1) -> 45957 | E10: =IF(Master_Data!M10="","",Master_Data!M10 - WEEKDAY(Master_Data!M10,2) + 1) -> 45964 | F10: =IF(Master_Data!N10="","",Master_Data!N10 - WEEKDAY(Master_Data!N10,2) + 1) -> 45992 | G10: =EOMONTH(Master_Data!H10,-1)+1 -> 45931 | H10: =IF(Master_Data!J10="","",EOMONTH(Master_Data!J10,-1)+1) -> 45931 | I10: =IF(Master_Data!M10="","",EOMONTH(Master_Data!M10,-1)+1) -> 45962 | J10: =IF(Master_Data!N10="","",EOMONTH(Master_Data!N10,-1)+1) -> 45992
A11: =Master_Data!D11 -> WLH/KEC/SIEC/DRAINAGE/3RD FL/00 | B11: =Master_Data!B11 -> MEP | C11: =IF(Master_Data!H11="","",Master_Data!H11 - WEEKDAY(Master_Data!H11,2) + 1) -> 45950 | D11: =IF(Master_Data!J11="","",Master_Data!J11 - WEEKDAY(Master_Data!J11,2) + 1) -> 45957 | E11: =IF(Master_Data!M11="","",Master_Data!M11 - WEEKDAY(Master_Data!M11,2) + 1) -> 45964 | F11: =IF(Master_Data!N11="","",Master_Data!N11 - WEEKDAY(Master_Data!N11,2) + 1) -> 45992 | G11: =EOMONTH(Master_Data!H11,-1)+1 -> 45931 | H11: =IF(Master_Data!J11="","",EOMONTH(Master_Data!J11,-1)+1) -> 45931 | I11: =IF(Master_Data!M11="","",EOMONTH(Master_Data!M11,-1)+1) -> 45962 | J11: =IF(Master_Data!N11="","",EOMONTH(Master_Data!N11,-1)+1) -> 45992
A12: =Master_Data!D12 -> WLH/KEC/SIEC/WATER SUPPLY/4TH FL/00 | B12: =Master_Data!B12 -> MEP | C12: =IF(Master_Data!H12="","",Master_Data!H12 - WEEKDAY(Master_Data!H12,2) + 1) -> 45789 | D12: =IF(Master_Data!J12="","",Master_Data!J12 - WEEKDAY(Master_Data!J12,2) + 1) -> 45796 | E12: =IF(Master_Data!M12="","",Master_Data!M12 - WEEKDAY(Master_Data!M12,2) + 1) -> 45803 | F12: =IF(Master_Data!N12="","",Master_Data!N12 - WEEKDAY(Master_Data!N12,2) + 1) -> 45810 | G12: =EOMONTH(Master_Data!H12,-1)+1 -> 45778 | H12: =IF(Master_Data!J12="","",EOMONTH(Master_Data!J12,-1)+1) -> 45778 | I12: =IF(Master_Data!M12="","",EOMONTH(Master_Data!M12,-1)+1) -> 45778 | J12: =IF(Master_Data!N12="","",EOMONTH(Master_Data!N12,-1)+1) -> 45809
A13: =Master_Data!D13 -> WLH/KEC/SIEC/DRAINAGE/4TH FL/00 | B13: =Master_Data!B13 -> MEP | C13: =IF(Master_Data!H13="","",Master_Data!H13 - WEEKDAY(Master_Data!H13,2) + 1) -> 45789 | D13: =IF(Master_Data!J13="","",Master_Data!J13 - WEEKDAY(Master_Data!J13,2) + 1) -> 45796 | E13: =IF(Master_Data!M13="","",Master_Data!M13 - WEEKDAY(Master_Data!M13,2) + 1) -> 45803 | F13: =IF(Master_Data!N13="","",Master_Data!N13 - WEEKDAY(Master_Data!N13,2) + 1) -> 45810 | G13: =EOMONTH(Master_Data!H13,-1)+1 -> 45778 | H13: =IF(Master_Data!J13="","",EOMONTH(Master_Data!J13,-1)+1) -> 45778 | I13: =IF(Master_Data!M13="","",EOMONTH(Master_Data!M13,-1)+1) -> 45809 | J13: =IF(Master_Data!N13="","",EOMONTH(Master_Data!N13,-1)+1) -> 45809
... A246: =Master_Data!D246 -> WLH/KEC/SIEC/HVAC/GR FL/SMOKE EXTRACTION/00-00 | B246: =Master_Data!B246 -> Structural | C246: =IF(Master_Data!H246="","",Master_Data!H246 - WEEKDAY(Master_Data!H246,2) + 1) -> 45747 | D246: =IF(Master_Data!J246="","",Master_Data!J246 - WEEKDAY(Master_Data!J246,2) + 1) -> 45754 | E246: =IF(Master_Data!M246="","",Master_Data!M246 - WEEKDAY(Master_Data!M246,2) + 1) -> 45761 | F246: =IF(Master_Data!N246="","",Master_Data!N246 - WEEKDAY(Master_Data!N246,2) + 1) -> 45810 | G246: =EOMONTH(Master_Data!H246,-1)+1 -> 45717 | H246: =IF(Master_Data!J246="","",EOMONTH(Master_Data!J246,-1)+1) -> 45748 | I246: =IF(Master_Data!M246="","",EOMONTH(Master_Data!M246,-1)+1) -> 45748 | J246: =IF(Master_Data!N246="","",EOMONTH(Master_Data!N246,-1)+1) -> 45809
A247: WLH/KEC/SIEC/HVAC/PRESSURIZATION/GR FL/00 | B247: =Master_Data!B247 -> Structural | C247: =IF(Master_Data!H247="","",Master_Data!H247 - WEEKDAY(Master_Data!H247,2) + 1) -> 45747 | D247: =IF(Master_Data!J247="","",Master_Data!J247 - WEEKDAY(Master_Data!J247,2) + 1) -> 45754 | E247: =IF(Master_Data!M247="","",Master_Data!M247 - WEEKDAY(Master_Data!M247,2) + 1) -> 45761 | F247: =IF(Master_Data!N247="","",Master_Data!N247 - WEEKDAY(Master_Data!N247,2) + 1) -> 45810 | G247: =EOMONTH(Master_Data!H247,-1)+1 -> 45717 | H247: =IF(Master_Data!J247="","",EOMONTH(Master_Data!J247,-1)+1) -> 45748 | I247: =IF(Master_Data!M247="","",EOMONTH(Master_Data!M247,-1)+1) -> 45748 | J247: =IF(Master_Data!N247="","",EOMONTH(Master_Data!N247,-1)+1) -> 45809
A248: WLH/KEC/SIEC/HVAC/1ST FL/DUCTING/00 | B248: =Master_Data!B248 -> Structural | C248: =IF(Master_Data!H248="","",Master_Data!H248 - WEEKDAY(Master_Data!H248,2) + 1) -> 45971 | D248: =IF(Master_Data!J248="","",Master_Data!J248 - WEEKDAY(Master_Data!J248,2) + 1) -> 45971 | E248: =IF(Master_Data!M248="","",Master_Data!M248 - WEEKDAY(Master_Data!M248,2) + 1) -> 45985 | F248: =IF(Master_Data!N248="","",Master_Data!N248 - WEEKDAY(Master_Data!N248,2) + 1) -> 45992 | G248: =EOMONTH(Master_Data!H248,-1)+1 -> 45962 | H248: =IF(Master_Data!J248="","",EOMONTH(Master_Data!J248,-1)+1) -> 45962 | I248: =IF(Master_Data!M248="","",EOMONTH(Master_Data!M248,-1)+1) -> 45962 | J248: =IF(Master_Data!N248="","",EOMONTH(Master_Data!N248,-1)+1) -> 45992
A249: WLH/KEC/SIEC/HVAC/1ST FL/CHW PIPING/00 | B249: =Master_Data!B249 -> Structural | C249: =IF(Master_Data!H249="","",Master_Data!H249 - WEEKDAY(Master_Data!H249,2) + 1) -> 45971 | D249: =IF(Master_Data!J249="","",Master_Data!J249 - WEEKDAY(Master_Data!J249,2) + 1) -> 45971 | E249: =IF(Master_Data!M249="","",Master_Data!M249 - WEEKDAY(Master_Data!M249,2) + 1) -> 45985 | F249: =IF(Master_Data!N249="","",Master_Data!N249 - WEEKDAY(Master_Data!N249,2) + 1) -> 45992 | G249: =EOMONTH(Master_Data!H249,-1)+1 -> 45962 | H249: =IF(Master_Data!J249="","",EOMONTH(Master_Data!J249,-1)+1) -> 45962 | I249: =IF(Master_Data!M249="","",EOMONTH(Master_Data!M249,-1)+1) -> 45962 | J249: =IF(Master_Data!N249="","",EOMONTH(Master_Data!N249,-1)+1) -> 45992
A250: WLH/KEC/SIEC/HVAC/1ST FL/SMOKE EXTRACTION/00 | B250: =Master_Data!B250 -> Structural | C250: =IF(Master_Data!H250="","",Master_Data!H250 - WEEKDAY(Master_Data!H250,2) + 1) -> 45971 | D250: =IF(Master_Data!J250="","",Master_Data!J250 - WEEKDAY(Master_Data!J250,2) + 1) -> 45971 | E250: =IF(Master_Data!M250="","",Master_Data!M250 - WEEKDAY(Master_Data!M250,2) + 1) -> 45985 | F250: =IF(Master_Data!N250="","",Master_Data!N250 - WEEKDAY(Master_Data!N250,2) + 1) -> 45992 | G250: =EOMONTH(Master_Data!H250,-1)+1 -> 45962 | H250: =IF(Master_Data!J250="","",EOMONTH(Master_Data!J250,-1)+1) -> 45962 | I250: =IF(Master_Data!M250="","",EOMONTH(Master_Data!M250,-1)+1) -> 45962 | J250: =IF(Master_Data!N250="","",EOMONTH(Master_Data!N250,-1)+1) -> 45992
A251: WLH/KEC/SIEC/HVAC/1ST FL/FRESH AIR/00 | B251: =Master_Data!B251 -> Structural | C251: =IF(Master_Data!H251="","",Master_Data!H251 - WEEKDAY(Master_Data!H251,2) + 1) -> 45971 | D251: =IF(Master_Data!J251="","",Master_Data!J251 - WEEKDAY(Master_Data!J251,2) + 1) -> 45971 | E251: =IF(Master_Data!M251="","",Master_Data!M251 - WEEKDAY(Master_Data!M251,2) + 1) -> 45985 | F251: =IF(Master_Data!N251="","",Master_Data!N251 - WEEKDAY(Master_Data!N251,2) + 1) -> 45992 | G251: =EOMONTH(Master_Data!H251,-1)+1 -> 45962 | H251: =IF(Master_Data!J251="","",EOMONTH(Master_Data!J251,-1)+1) -> 45962 | I251: =IF(Master_Data!M251="","",EOMONTH(Master_Data!M251,-1)+1) -> 45962 | J251: =IF(Master_Data!N251="","",EOMONTH(Master_Data!N251,-1)+1) -> 45992
A252: WLH/KEC/SIEC/HVAC/PRESSURIZATION/1STFL/00 | B252: =Master_Data!B252 -> Structural | C252: =IF(Master_Data!H252="","",Master_Data!H252 - WEEKDAY(Master_Data!H252,2) + 1) -> 45971 | D252: =IF(Master_Data!J252="","",Master_Data!J252 - WEEKDAY(Master_Data!J252,2) + 1) -> 45971 | E252: =IF(Master_Data!M252="","",Master_Data!M252 - WEEKDAY(Master_Data!M252,2) + 1) -> 45985 | F252: =IF(Master_Data!N252="","",Master_Data!N252 - WEEKDAY(Master_Data!N252,2) + 1) -> 45992 | G252: =EOMONTH(Master_Data!H252,-1)+1 -> 45962 | H252: =IF(Master_Data!J252="","",EOMONTH(Master_Data!J252,-1)+1) -> 45962 | I252: =IF(Master_Data!M252="","",EOMONTH(Master_Data!M252,-1)+1) -> 45962 | J252: =IF(Master_Data!N252="","",EOMONTH(Master_Data!N252,-1)+1) -> 45992
A253: WLH/KEC/SIEC/HVAC/2ND FL/DUCTING/00 | B253: =Master_Data!B253 -> Structural | C253: =IF(Master_Data!H253="","",Master_Data!H253 - WEEKDAY(Master_Data!H253,2) + 1) -> 45957 | D253: =IF(Master_Data!J253="","",Master_Data!J253 - WEEKDAY(Master_Data!J253,2) + 1) -> 45964 | E253: =IF(Master_Data!M253="","",Master_Data!M253 - WEEKDAY(Master_Data!M253,2) + 1) -> 45971 | F253: =IF(Master_Data!N253="","",Master_Data!N253 - WEEKDAY(Master_Data!N253,2) + 1) -> 45992 | G253: =EOMONTH(Master_Data!H253,-1)+1 -> 45931 | H253: =IF(Master_Data!J253="","",EOMONTH(Master_Data!J253,-1)+1) -> 45962 | I253: =IF(Master_Data!M253="","",EOMONTH(Master_Data!M253,-1)+1) -> 45962 | J253: =IF(Master_Data!N253="","",EOMONTH(Master_Data!N253,-1)+1) -> 45992
A254: WLH/KEC/SIEC/HVAC/2ND FL/CHW PIPING/00 | B254: =Master_Data!B254 -> Structural | C254: =IF(Master_Data!H254="","",Master_Data!H254 - WEEKDAY(Master_Data!H254,2) + 1) -> 45957 | D254: =IF(Master_Data!J254="","",Master_Data!J254 - WEEKDAY(Master_Data!J254,2) + 1) -> 45964 | E254: =IF(Master_Data!M254="","",Master_Data!M254 - WEEKDAY(Master_Data!M254,2) + 1) -> 45971 | F254: =IF(Master_Data!N254="","",Master_Data!N254 - WEEKDAY(Master_Data!N254,2) + 1) -> 45992 | G254: =EOMONTH(Master_Data!H254,-1)+1 -> 45931 | H254: =IF(Master_Data!J254="","",EOMONTH(Master_Data!J254,-1)+1) -> 45962 | I254: =IF(Master_Data!M254="","",EOMONTH(Master_Data!M254,-1)+1) -> 45962 | J254: =IF(Master_Data!N254="","",EOMONTH(Master_Data!N254,-1)+1) -> 45992
A255: WLH/KEC/SIEC/HVAC/2ND FL/SMOKE EXTRACTION/00 | B255: =Master_Data!B255 -> Structural | C255: =IF(Master_Data!H255="","",Master_Data!H255 - WEEKDAY(Master_Data!H255,2) + 1) -> 45957 | D255: =IF(Master_Data!J255="","",Master_Data!J255 - WEEKDAY(Master_Data!J255,2) + 1) -> 45964 | E255: =IF(Master_Data!M255="","",Master_Data!M255 - WEEKDAY(Master_Data!M255,2) + 1) -> 45971 | F255: =IF(Master_Data!N255="","",Master_Data!N255 - WEEKDAY(Master_Data!N255,2) + 1) -> 45992 | G255: =EOMONTH(Master_Data!H255,-1)+1 -> 45931 | H255: =IF(Master_Data!J255="","",EOMONTH(Master_Data!J255,-1)+1) -> 45962 | I255: =IF(Master_Data!M255="","",EOMONTH(Master_Data!M255,-1)+1) -> 45962 | J255: =IF(Master_Data!N255="","",EOMONTH(Master_Data!N255,-1)+1) -> 45992
A256: WLH/KEC/SIEC/HVAC/2ND FL/FRESH AIR/00 | B256: =Master_Data!B256 -> Structural | C256: =IF(Master_Data!H256="","",Master_Data!H256 - WEEKDAY(Master_Data!H256,2) + 1) -> 45957 | D256: =IF(Master_Data!J256="","",Master_Data!J256 - WEEKDAY(Master_Data!J256,2) + 1) -> 45964 | E256: =IF(Master_Data!M256="","",Master_Data!M256 - WEEKDAY(Master_Data!M256,2) + 1) -> 45971 | F256: =IF(Master_Data!N256="","",Master_Data!N256 - WEEKDAY(Master_Data!N256,2) + 1) -> 45992 | G256: =EOMONTH(Master_Data!H256,-1)+1 -> 45931 | H256: =IF(Master_Data!J256="","",EOMONTH(Master_Data!J256,-1)+1) -> 45962 | I256: =IF(Master_Data!M256="","",EOMONTH(Master_Data!M256,-1)+1) -> 45962 | J256: =IF(Master_Data!N256="","",EOMONTH(Master_Data!N256,-1)+1) -> 45992
A257: WLH/KEC/SIEC/HVAC/PRESSURIZATION/2ND FL/00 | B257: =Master_Data!B257 -> Structural | C257: =IF(Master_Data!H257="","",Master_Data!H257 - WEEKDAY(Master_Data!H257,2) + 1) -> 45957 | D257: =IF(Master_Data!J257="","",Master_Data!J257 - WEEKDAY(Master_Data!J257,2) + 1) -> 45964 | E257: =IF(Master_Data!M257="","",Master_Data!M257 - WEEKDAY(Master_Data!M257,2) + 1) -> 45971 | F257: =IF(Master_Data!N257="","",Master_Data!N257 - WEEKDAY(Master_Data!N257,2) + 1) -> 45992 | G257: =EOMONTH(Master_Data!H257,-1)+1 -> 45931 | H257: =IF(Master_Data!J257="","",EOMONTH(Master_Data!J257,-1)+1) -> 45962 | I257: =IF(Master_Data!M257="","",EOMONTH(Master_Data!M257,-1)+1) -> 45962 | J257: =IF(Master_Data!N257="","",EOMONTH(Master_Data!N257,-1)+1) -> 45992
A258: WLH/KEC/SIEC/HVAC/3RD FL/DUCTING/00 | B258: =Master_Data!B258 -> Structural | C258: =IF(Master_Data!H258="","",Master_Data!H258 - WEEKDAY(Master_Data!H258,2) + 1) -> 45950 | D258: =IF(Master_Data!J258="","",Master_Data!J258 - WEEKDAY(Master_Data!J258,2) + 1) -> 45957 | E258: =IF(Master_Data!M258="","",Master_Data!M258 - WEEKDAY(Master_Data!M258,2) + 1) -> 45964 | F258: =IF(Master_Data!N258="","",Master_Data!N258 - WEEKDAY(Master_Data!N258,2) + 1) -> 45992 | G258: =EOMONTH(Master_Data!H258,-1)+1 -> 45931 | H258: =IF(Master_Data!J258="","",EOMONTH(Master_Data!J258,-1)+1) -> 45931 | I258: =IF(Master_Data!M258="","",EOMONTH(Master_Data!M258,-1)+1) -> 45962 | J258: =IF(Master_Data!N258="","",EOMONTH(Master_Data!N258,-1)+1) -> 45992
... A543: WMHL-EX-A44-06 | B543: =Master_Data!B543 -> Structural | C543: =IF(Master_Data!H543="","",Master_Data!H543 - WEEKDAY(Master_Data!H543,2) + 1) -> 46055 | D543: =IF(Master_Data!J543="","",Master_Data!J543 - WEEKDAY(Master_Data!J543,2) + 1) -> 46055 | E543: =IF(Master_Data!M543="","",Master_Data!M543 - WEEKDAY(Master_Data!M543,2) + 1) -> 46083 | F543: =IF(Master_Data!N543="","",Master_Data!N543 - WEEKDAY(Master_Data!N543,2) + 1) -> 46132 | G543: =EOMONTH(Master_Data!H543,-1)+1 -> 46054 | H543: =IF(Master_Data!J543="","",EOMONTH(Master_Data!J543,-1)+1) -> 46054 | I543: =IF(Master_Data!M543="","",EOMONTH(Master_Data!M543,-1)+1) -> 46082 | J543: =IF(Master_Data!N543="","",EOMONTH(Master_Data!N543,-1)+1) -> 46113

Sheet S_Curve_Data
B1: Column Labels | F1: Structural | G1: =HLOOKUP(F1,$B$2:$D$3,2,FALSE) -> 183 | M1: Architecture | N1: =HLOOKUP(M1,$B$2:$D$3,2,FALSE) -> 123 | T1: MEP | U1: =HLOOKUP(T1,$B$2:$D$3,2,FALSE) -> 236 | AA1: Structural | AB1: =HLOOKUP(AA1,$B$2:$D$3,2,FALSE) -> 183 | AH1: Architecture | AI1: =HLOOKUP(AH1,$B$2:$D$3,2,FALSE) -> 123 | AO1: MEP | AP1: =HLOOKUP(AO1,$B$2:$D$3,2,FALSE) -> 236
B2: Architecture | C2: MEP | D2: Structural | F2: Rpt_Week | G2: Submission_1 Plan | H2: Submission_1 Actuals | I2: Approval Plan | J2: Approval Actuals | M2: Rpt_Week | N2: Submission_1 Plan | O2: Submission_1 Actuals | P2: Approval Plan | Q2: Approval Actuals | T2: Rpt_Week | U2: Submission_1 Plan | V2: Submission_1 Actuals | W2: Approval Plan | X2: Approval Actuals | AA2: Rpt_Month | AB2: Submission_1 Plan | AC2: Submission_1 Actuals | AD2: Approval Plan | AE2: Approval Actuals | AH2: Rpt_Month | AI2: Submission_1 Plan | AJ2: Submission_1 Actuals | AK2: Approval Plan | AL2: Approval Actuals | AO2: Rpt_Month | AP2: Submission_1 Plan | AQ2: Submission_1 Actuals | AR2: Approval Plan | AS2: Approval Actuals
A3: Total DRG ID | B3: 123 | C3: 236 | D3: 183 | F3: =Mappings!B2 -> 45663 | G3: {=IFERROR(ROWS(_xlfn._xlws.FILTER( DRG_Status!$A$2:$A$100000, (DRG_Status!$C$2:$C$100000=S_Curve_Data!F3) * (DRG_Status!$B$2:$B$100000=S_Curve_Data!$F$1) )),0)/$G$1} -> 0 | H3: {=IFERROR(ROWS(_xlfn._xlws.FILTER( DRG_Status!$A$2:$A$100000, (DRG_Status!$D$2:$D$100000=S_Curve_Data!F3) * (DRG_Status!$B$2:$B$100000=S_Curve_Data!$F$1) )),0)/$G$1} -> 0 | I3: {=IFERROR(ROWS(_xlfn._xlws.FILTER( DRG_Status!$A$2:$A$100000, (DRG_Status!$E$2:$E$100000=S_Curve_Data!F3) * (DRG_Status!$B$2:$B$100000=S_Curve_Data!$F$1) )),0)/$G$1} -> 0 | J3: {=IFERROR(ROWS(_xlfn._xlws.FILTER( DRG_Status!$A$2:$A$100000, (DRG_Status!$F$2:$F$100000=S_Curve_Data!F3) * (DRG_Status!$B$2:$B$100000=S_Curve_Data!$F$1) )),0)/$G$1} -> 0 | M3: =Mappings!B2 -> 45663 | N3: {=IFERROR(ROWS(_xlfn._xlws.FILTER( DRG_Status!$A$2:$A$100000, (DRG_Status!$C$2:$C$100000=S_Curve_Data!M3) * (DRG_Status!$B$2:$B$100000=S_Curve_Data!$M$1) )),0)/$N$1} -> 0 | O3: {=IFERROR(ROWS(_xlfn._xlws.FILTER( DRG_Status!$A$2:$A$100000, (DRG_Status!$D$2:$D$100000=S_Curve_Data!M3) * (DRG_Status!$B$2:$B$100000=S_Curve_Data!$M$1) )),0)/$N$1} -> 0 | P3: {=IFERROR(ROWS(_xlfn._xlws.FILTER( DRG_Status!$A$2:$A$100000, (DRG_Status!$E$2:$E$100000=S_Curve_Data!M3) * (DRG_Status!$B$2:$B$100000=S_Curve_Data!$M$1) )),0)/$N$1} -> 0 | Q3: {=IFERROR(ROWS(_xlfn._xlws.FILTER( DRG_Status!$A$2:$A$100000, (DRG_Status!$F$2:$F$100000=S_Curve_Data!M3) * (DRG_Status!$B$2:$B$100000=S_Curve_Data!$M$1) )),0)/$N$1} -> 0 | T3: =Mappings!B2 -> 45663 | U3: {=IFERROR(ROWS(_xlfn._xlws.FILTER( DRG_Status!$A$2:$A$100000, (DRG_Status!$C$2:$C$100000=S_Curve_Data!T3) * (DRG_Status!$B$2:$B$100000=S_Curve_Data!$T$1) )),0)/$U$1} -> 0 | V3: {=IFERROR(ROWS(_xlfn._xlws.FILTER( DRG_Status!$A$2:$A$100000, (DRG_Status!$D$2:$D$100000=S_Curve_Data!T3) * (DRG_Status!$B$2:$B$100000=S_Curve_Data!$T$1) )),0)/$U$1} -> 0 | W3: {=IFERROR(ROWS(_xlfn._xlws.FILTER( DRG_Status!$A$2:$A$100000, (DRG_Status!$E$2:$E$100000=S_Curve_Data!T3) * (DRG_Status!$B$2:$B$100000=S_Curve_Data!$T$1) )),0)/$U$1} -> 0 | X3: {=IFERROR(ROWS(_xlfn._xlws.FILTER( DRG_Status!$A$2:$A$100000, (DRG_Status!$F$2:$F$100000=S_Curve_Data!T3) * (DRG_Status!$B$2:$B$100000=S_Curve_Data!$T$1) )),0)/$U$1} -> 0 | AA3: 45658 | AB3: {=IFERROR(ROWS(_xlfn._xlws.FILTER( DRG_Status!$A$2:$A$100000, (DRG_Status!$G$2:$G$100000=S_Curve_Data!AA3) * (DRG_Status!$B$2:$B$100000=S_Curve_Data!$AA$1) )),0)/$AB$1} -> 0 | AC3: {=IFERROR(ROWS(_xlfn._xlws.FILTER( DRG_Status!$A$2:$A$100000, (DRG_Status!$H$2:$H$100000=S_Curve_Data!AA3) * (DRG_Status!$B$2:$B$100000=S_Curve_Data!$AA$1) )),0)/$AB$1} -> 0 | AD3: {=IFERROR(ROWS(_xlfn._xlws.FILTER( DRG_Status!$A$2:$A$100000, (DRG_Status!$I$2:$I$100000=S_Curve_Data!AA3) * (DRG_Status!$B$2:$B$100000=S_Curve_Data!$AA$1) )),0)/$AB$1} -> 0 | AE3: {=IFERROR(ROWS(_xlfn._xlws.FILTER( DRG_Status!$A$2:$A$100000, (DRG_Status!$J$2:$J$100000=S_Curve_Data!AA3) * (DRG_Status!$B$2:$B$100000=S_Curve_Data!$AA$1) )),0)/$AB$1} -> 0 | AH3: 45658 | AI3: {=IFERROR(ROWS(_xlfn._xlws.FILTER( DRG_Status!$A$2:$A$100000, (DRG_Status!$G$2:$G$100000=S_Curve_Data!AH3) * (DRG_Status!$B$2:$B$100000=S_Curve_Data!$AH$1) )),0)/$AI$1} -> 0 | AJ3: {=IFERROR(ROWS(_xlfn._xlws.FILTER( DRG_Status!$A$2:$A$100000, (DRG_Status!$H$2:$H$100000=S_Curve_Data!AH3) * (DRG_Status!$B$2:$B$100000=S_Curve_Data!$AH$1) )),0)/$AI$1} -> 0 | AK3: {=IFERROR(ROWS(_xlfn._xlws.FILTER( DRG_Status!$A$2:$A$100000, (DRG_Status!$I$2:$I$100000=S_Curve_Data!AH3) * (DRG_Status!$B$2:$B$100000=S_Curve_Data!$AH$1) )),0)/$AI$1} -> 0 | AL3: {=IFERROR(ROWS(_xlfn._xlws.FILTER( DRG_Status!$A$2:$A$100000, (DRG_Status!$J$2:$J$100000=S_Curve_Data!AH3) * (DRG_Status!$B$2:$B$100000=S_Curve_Data!$AH$1) )),0)/$AI$1} -> 0 | AO3: 45658 | AP3: {=IFERROR(ROWS(_xlfn._xlws.FILTER( DRG_Status!$A$2:$A$100000, (DRG_Status!$G$2:$G$100000=S_Curve_Data!AO3) * (DRG_Status!$B$2:$B$100000=S_Curve_Data!$AO$1) )),0)/$AP$1} -> 0 | AQ3: {=IFERROR(ROWS(_xlfn._xlws.FILTER( DRG_Status!$A$2:$A$100000, (DRG_Status!$H$2:$H$100000=S_Curve_Data!AO3) * (DRG_Status!$B$2:$B$100000=S_Curve_Data!$AO$1) )),0)/$AP$1} -> 0 | AR3: {=IFERROR(ROWS(_xlfn._xlws.FILTER( DRG_Status!$A$2:$A$100000, (DRG_Status!$I$2:$I$100000=S_Curve_Data!AO3) * (DRG_Status!$B$2:$B$100000=S_Curve_Data!$AO$1) )),0)/$AP$1} -> 0 | AS3: {=IFERROR(ROWS(_xlfn._xlws.FILTER( DRG_Status!$A$2:$A$100000, (DRG_Status!$J$2:$J$100000=S_Curve_Data!AO3) * (DRG_Status!$B$2:$B$100000=S_Curve_Data!$AO$1) )),0)/$AP$1} -> 0
F4: =Mappings!B3 -> 45670 | G4: {=IFERROR(ROWS(_xlfn._xlws.FILTER( DRG_Status!$A$2:$A$100000, (DRG_Status!$C$2:$C$100000=S_Curve_Data!F4) * (DRG_Status!$B$2:$B$100000=S_Curve_Data!$F$1) )),0)/$G$1} -> 0 | H4: {=IFERROR(ROWS(_xlfn._xlws.FILTER( DRG_Status!$A$2:$A$100000, (DRG_Status!$D$2:$D$100000=S_Curve_Data!F4) * (DRG_Status!$B$2:$B$100000=S_Curve_Data!$F$1) )),0)/$G$1} -> 0 | I4: {=IFERROR(ROWS(_xlfn._xlws.FILTER( DRG_Status!$A$2:$A$100000, (DRG_Status!$E$2:$E$100000=S_Curve_Data!F4) * (DRG_Status!$B$2:$B$100000=S_Curve_Data!$F$1) )),0)/$G$1} -> 0 | J4: {=IFERROR(ROWS(_xlfn._xlws.FILTER( DRG_Status!$A$2:$A$100000, (DRG_Status!$F$2:$F$100000=S_Curve_Data!F4) * (DRG_Status!$B$2:$B$100000=S_Curve_Data!$F$1) )),0)/$G$1} -> 0 | M4: =Mappings!B3 -> 45670 | N4: {=IFERROR(ROWS(_xlfn._xlws.FILTER( DRG_Status!$A$2:$A$100000, (DRG_Status!$C$2:$C$100000=S_Curve_Data!M4) * (DRG_Status!$B$2:$B$100000=S_Curve_Data!$M$1) )),0)/$N$1} -> 0 | O4: {=IFERROR(ROWS(_xlfn._xlws.FILTER( DRG_Status!$A$2:$A$100000, (DRG_Status!$D$2:$D$100000=S_Curve_Data!M4) * (DRG_Status!$B$2:$B$100000=S_Curve_Data!$M$1) )),0)/$N$1} -> 0 | P4: {=IFERROR(ROWS(_xlfn._xlws.FILTER( DRG_Status!$A$2:$A$100000, (DRG_Status!$E$2:$E$100000=S_Curve_Data!M4) * (DRG_Status!$B$2:$B$100000=S_Curve_Data!$M$1) )),0)/$N$1} -> 0 | Q4: {=IFERROR(ROWS(_xlfn._xlws.FILTER( DRG_Status!$A$2:$A$100000, (DRG_Status!$F$2:$F$100000=S_Curve_Data!M4) * (DRG_Status!$B$2:$B$100000=S_Curve_Data!$M$1) )),0)/$N$1} -> 0 | T4: =Mappings!B3 -> 45670 | U4: {=IFERROR(ROWS(_xlfn._xlws.FILTER( DRG_Status!$A$2:$A$100000, (DRG_Status!$C$2:$C$100000=S_Curve_Data!T4) * (DRG_Status!$B$2:$B$100000=S_Curve_Data!$T$1) )),0)/$U$1} -> 0 | V4: {=IFERROR(ROWS(_xlfn._xlws.FILTER( DRG_Status!$A$2:$A$100000, (DRG_Status!$D$2:$D$100000=S_Curve_Data!T4) * (DRG_Status!$B$2:$B$100000=S_Curve_Data!$T$1) )),0)/$U$1} -> 0 | W4: {=IFERROR(ROWS(_xlfn._xlws.FILTER( DRG_Status!$A$2:$A$100000, (DRG_Status!$E$2:$E$100000=S_Curve_Data!T4) * (DRG_Status!$B$2:$B$100000=S_Curve_Data!$T$1) )),0)/$U$1} -> 0 | X4: {=IFERROR(ROWS(_xlfn._xlws.FILTER( DRG_Status!$A$2:$A$100000, (DRG_Status!$F$2:$F$100000=S_Curve_Data!T4) * (DRG_Status!$B$2:$B$100000=S_Curve_Data!$T$1) )),0)/$U$1} -> 0 | AA4: 45689 | AB4: {=IFERROR(ROWS(_xlfn._xlws.FILTER( DRG_Status!$A$2:$A$100000, (DRG_Status!$G$2:$G$100000=S_Curve_Data!AA4) * (DRG_Status!$B$2:$B$100000=S_Curve_Data!$AA$1) )),0)/$AB$1} -> 0 | AC4: {=IFERROR(ROWS(_xlfn._xlws.FILTER( DRG_Status!$A$2:$A$100000, (DRG_Status!$H$2:$H$100000=S_Curve_Data!AA4) * (DRG_Status!$B$2:$B$100000=S_Curve_Data!$AA$1) )),0)/$AB$1} -> 0 | AD4: {=IFERROR(ROWS(_xlfn._xlws.FILTER( DRG_Status!$A$2:$A$100000, (DRG_Status!$I$2:$I$100000=S_Curve_Data!AA4) * (DRG_Status!$B$2:$B$100000=S_Curve_Data!$AA$1) )),0)/$AB$1} -> 0 | AE4: {=IFERROR(ROWS(_xlfn._xlws.FILTER( DRG_Status!$A$2:$A$100000, (DRG_Status!$J$2:$J$100000=S_Curve_Data!AA4) * (DRG_Status!$B$2:$B$100000=S_Curve_Data!$AA$1) )),0)/$AB$1} -> 0 | AH4: 45689 | AI4: {=IFERROR(ROWS(_xlfn._xlws.FILTER( DRG_Status!$A$2:$A$100000, (DRG_Status!$G$2:$G$100000=S_Curve_Data!AH4) * (DRG_Status!$B$2:$B$100000=S_Curve_Data!$AH$1) )),0)/$AI$1} -> 0 | AJ4: {=IFERROR(ROWS(_xlfn._xlws.FILTER( DRG_Status!$A$2:$A$100000, (DRG_Status!$H$2:$H$100000=S_Curve_Data!AH4) * (DRG_Status!$B$2:$B$100000=S_Curve_Data!$AH$1) )),0)/$AI$1} -> 0 | AK4: {=IFERROR(ROWS(_xlfn._xlws.FILTER( DRG_Status!$A$2:$A$100000, (DRG_Status!$I$2:$I$100000=S_Curve_Data!AH4) * (DRG_Status!$B$2:$B$100000=S_Curve_Data!$AH$1) )),0)/$AI$1} -> 0 | AL4: {=IFERROR(ROWS(_xlfn._xlws.FILTER( DRG_Status!$A$2:$A$100000, (DRG_Status!$J$2:$J$100000=S_Curve_Data!AH4) * (DRG_Status!$B$2:$B$100000=S_Curve_Data!$AH$1) )),0)/$AI$1} -> 0 | AO4: 45689 | AP4: {=IFERROR(ROWS(_xlfn._xlws.FILTER( DRG_Status!$A$2:$A$100000, (DRG_Status!$G$2:$G$100000=S_Curve_Data!AO4) * (DRG_Status!$B$2:$B$100000=S_Curve_Data!$AO$1) )),0)/$AP$1} -> 0 | AQ4: {=IFERROR(ROWS(_xlfn._xlws.FILTER( DRG_Status!$A$2:$A$100000, (DRG_Status!$H$2:$H$100000=S_Curve_Data!AO4) * (DRG_Status!$B$2:$B$100000=S_Curve_Data!$AO$1) )),0)/$AP$1} -> 0 | AR4: {=IFERROR(ROWS(_xlfn._xlws.FILTER( DRG_Status!$A$2:$A$100000, (DRG_Status!$I$2:$I$100000=S_Curve_Data!AO4) * (DRG_Status!$B$2:$B$100000=S_Curve_Data!$AO$1) )),0)/$AP$1} -> 0 | AS4: {=IFERROR(ROWS(_xlfn._xlws.FILTER( DRG_Status!$A$2:$A$100000, (DRG_Status!$J$2:$J$100000=S_Curve_Data!AO4) * (DRG_Status!$B$2:$B$100000=S_Curve_Data!$AO$1) )),0)/$AP$1} -> 0
F5: =Mappings!B4 -> 45677 | G5: {=IFERROR(ROWS(_xlfn._xlws.FILTER( DRG_Status!$A$2:$A$100000, (DRG_Status!$C$2:$C$100000=S_Curve_Data!F5) * (DRG_Status!$B$2:$B$100000=S_Curve_Data!$F$1) )),0)/$G$1} -> 0 | H5: {=IFERROR(ROWS(_xlfn._xlws.FILTER( DRG_Status!$A$2:$A$100000, (DRG_Status!$D$2:$D$100000=S_Curve_Data!F5) * (DRG_Status!$B$2:$B$100000=S_Curve_Data!$F$1) )),0)/$G$1} -> 0 | I5: {=IFERROR(ROWS(_xlfn._xlws.FILTER( DRG_Status!$A$2:$A$100000, (DRG_Status!$E$2:$E$100000=S_Curve_Data!F5) * (DRG_Status!$B$2:$B$100000=S_Curve_Data!$F$1) )),0)/$G$1} -> 0 | J5: {=IFERROR(ROWS(_xlfn._xlws.FILTER( DRG_Status!$A$2:$A$100000, (DRG_Status!$F$2:$F$100000=S_Curve_Data!F5) * (DRG_Status!$B$2:$B$100000=S_Curve_Data!$F$1) )),0)/$G$1} -> 0 | M5: =Mappings!B4 -> 45677 | N5: {=IFERROR(ROWS(_xlfn._xlws.FILTER( DRG_Status!$A$2:$A$100000, (DRG_Status!$C$2:$C$100000=S_Curve_Data!M5) * (DRG_Status!$B$2:$B$100000=S_Curve_Data!$M$1) )),0)/$N$1} -> 0 | O5: {=IFERROR(ROWS(_xlfn._xlws.FILTER( DRG_Status!$A$2:$A$100000, (DRG_Status!$D$2:$D$100000=S_Curve_Data!M5) * (DRG_Status!$B$2:$B$100000=S_Curve_Data!$M$1) )),0)/$N$1} -> 0 | P5: {=IFERROR(ROWS(_xlfn._xlws.FILTER( DRG_Status!$A$2:$A$100000, (DRG_Status!$E$2:$E$100000=S_Curve_Data!M5) * (DRG_Status!$B$2:$B$100000=S_Curve_Data!$M$1) )),0)/$N$1} -> 0 | Q5: {=IFERROR(ROWS(_xlfn._xlws.FILTER( DRG_Status!$A$2:$A$100000, (DRG_Status!$F$2:$F$100000=S_Curve_Data!M5) * (DRG_Status!$B$2:$B$100000=S_Curve_Data!$M$1) )),0)/$N$1} -> 0 | T5: =Mappings!B4 -> 45677 | U5: {=IFERROR(ROWS(_xlfn._xlws.FILTER( DRG_Status!$A$2:$A$100000, (DRG_Status!$C$2:$C$100000=S_Curve_Data!T5) * (DRG_Status!$B$2:$B$100000=S_Curve_Data!$T$1) )),0)/$U$1} -> 0 | V5: {=IFERROR(ROWS(_xlfn._xlws.FILTER( DRG_Status!$A$2:$A$100000, (DRG_Status!$D$2:$D$100000=S_Curve_Data!T5) * (DRG_Status!$B$2:$B$100000=S_Curve_Data!$T$1) )),0)/$U$1} -> 0 | W5: {=IFERROR(ROWS(_xlfn._xlws.FILTER( DRG_Status!$A$2:$A$100000, (DRG_Status!$E$2:$E$100000=S_Curve_Data!T5) * (DRG_Status!$B$2:$B$100000=S_Curve_Data!$T$1) )),0)/$U$1} -> 0 | X5: {=IFERROR(ROWS(_xlfn._xlws.FILTER( DRG_Status!$A$2:$A$100000, (DRG_Status!$F$2:$F$100000=S_Curve_Data!T5) * (DRG_Status!$B$2:$B$100000=S_Curve_Data!$T$1) )),0)/$U$1} -> 0 | AA5: 45717 | AB5: {=IFERROR(ROWS(_xlfn._xlws.FILTER( DRG_Status!$A$2:$A$100000, (DRG_Status!$G$2:$G$100000=S_Curve_Data!AA5) * (DRG_Status!$B$2:$B$100000=S_Curve_Data!$AA$1) )),0)/$AB$1} -> 0.20218579 | AC5: {=IFERROR(ROWS(_xlfn._xlws.FILTER( DRG_Status!$A$2:$A$100000, (DRG_Status!$H$2:$H$100000=S_Curve_Data!AA5) * (DRG_Status!$B$2:$B$100000=S_Curve_Data!$AA$1) )),0)/$AB$1} -> 0.14754098 | AD5: {=IFERROR(ROWS(_xlfn._xlws.FILTER( DRG_Status!$A$2:$A$100000, (DRG_Status!$I$2:$I$100000=S_Curve_Data!AA5) * (DRG_Status!$B$2:$B$100000=S_Curve_Data!$AA$1) )),0)/$AB$1} -> 0.081967213 | AE5: {=IFERROR(ROWS(_xlfn._xlws.FILTER( DRG_Status!$A$2:$A$100000, (DRG_Status!$J$2:$J$100000=S_Curve_Data!AA5) * (DRG_Status!$B$2:$B$100000=S_Curve_Data!$AA$1) )),0)/$AB$1} -> 0.081967213 | AH5: 45717 | AI5: {=IFERROR(ROWS(_xlfn._xlws.FILTER( DRG_Status!$A$2:$A$100000, (DRG_Status!$G$2:$G$100000=S_Curve_Data!AH5) * (DRG_Status!$B$2:$B$100000=S_Curve_Data!$AH$1) )),0)/$AI$1} -> 0.13821138 | AJ5: {=IFERROR(ROWS(_xlfn._xlws.FILTER( DRG_Status!$A$2:$A$100000, (DRG_Status!$H$2:$H$100000=S_Curve_Data!AH5) * (DRG_Status!$B$2:$B$100000=S_Curve_Data!$AH$1) )),0)/$AI$1} -> 0.14634146 | AK5: {=IFERROR(ROWS(_xlfn._xlws.FILTER( DRG_Status!$A$2:$A$100000, (DRG_Status!$I$2:$I$100000=S_Curve_Data!AH5) * (DRG_Status!$B$2:$B$100000=S_Curve_Data!$AH$1) )),0)/$AI$1} -> 0.13821138 | AL5: {=IFERROR(ROWS(_xlfn._xlws.FILTER( DRG_Status!$A$2:$A$100000, (DRG_Status!$J$2:$J$100000=S_Curve_Data!AH5) * (DRG_Status!$B$2:$B$100000=S_Curve_Data!$AH$1) )),0)/$AI$1} -> 0.13821138 | AO5: 45717 | AP5: {=IFERROR(ROWS(_xlfn._xlws.FILTER( DRG_Status!$A$2:$A$100000, (DRG_Status!$G$2:$G$100000=S_Curve_Data!AO5) * (DRG_Status!$B$2:$B$100000=S_Curve_Data!$AO$1) )),0)/$AP$1} -> 0.30084746 | AQ5: {=IFERROR(ROWS(_xlfn._xlws.FILTER( DRG_Status!$A$2:$A$100000, (DRG_Status!$H$2:$H$100000=S_Curve_Data!AO5) * (DRG_Status!$B$2:$B$100000=S_Curve_Data!$AO$1) )),0)/$AP$1} -> 0.093220339 | AR5: {=IFERROR(ROWS(_xlfn._xlws.FILTER( DRG_Status!$A$2:$A$100000, (DRG_Status!$I$2:$I$100000=S_Curve_Data!AO5) * (DRG_Status!$B$2:$B$100000=S_Curve_Data!$AO$1) )),0)/$AP$1} -> 0 | AS5: {=IFERROR(ROWS(_xlfn._xlws.FILTER( DRG_Status!$A$2:$A$100000, (DRG_Status!$J$2:$J$100000=S_Curve_Data!AO5) * (DRG_Status!$B$2:$B$100000=S_Curve_Data!$AO$1) )),0)/$AP$1} -> 0.0042372881
F6: =Mappings!B5 -> 45684 | G6: {=IFERROR(ROWS(_xlfn._xlws.FILTER( DRG_Status!$A$2:$A$100000, (DRG_Status!$C$2:$C$100000=S_Curve_Data!F6) * (DRG_Status!$B$2:$B$100000=S_Curve_Data!$F$1) )),0)/$G$1} -> 0 | H6: {=IFERROR(ROWS(_xlfn._xlws.FILTER( DRG_Status!$A$2:$A$100000, (DRG_Status!$D$2:$D$100000=S_Curve_Data!F6) * (DRG_Status!$B$2:$B$100000=S_Curve_Data!$F$1) )),0)/$G$1} -> 0 | I6: {=IFERROR(ROWS(_xlfn._xlws.FILTER( DRG_Status!$A$2:$A$100000, (DRG_Status!$E$2:$E$100000=S_Curve_Data!F6) * (DRG_Status!$B$2:$B$100000=S_Curve_Data!$F$1) )),0)/$G$1} -> 0 | J6: {=IFERROR(ROWS(_xlfn._xlws.FILTER( DRG_Status!$A$2:$A$100000, (DRG_Status!$F$2:$F$100000=S_Curve_Data!F6) * (DRG_Status!$B$2:$B$100000=S_Curve_Data!$F$1) )),0)/$G$1} -> 0 | M6: =Mappings!B5 -> 45684 | N6: {=IFERROR(ROWS(_xlfn._xlws.FILTER( DRG_Status!$A$2:$A$100000, (DRG_Status!$C$2:$C$100000=S_Curve_Data!M6) * (DRG_Status!$B$2:$B$100000=S_Curve_Data!$M$1) )),0)/$N$1} -> 0 | O6: {=IFERROR(ROWS(_xlfn._xlws.FILTER( DRG_Status!$A$2:$A$100000, (DRG_Status!$D$2:$D$100000=S_Curve_Data!M6) * (DRG_Status!$B$2:$B$100000=S_Curve_Data!$M$1) )),0)/$N$1} -> 0 | P6: {=IFERROR(ROWS(_xlfn._xlws.FILTER( DRG_Status!$A$2:$A$100000, (DRG_Status!$E$2:$E$100000=S_Curve_Data!M6) * (DRG_Status!$B$2:$B$100000=S_Curve_Data!$M$1) )),0)/$N$1} -> 0 | Q6: {=IFERROR(ROWS(_xlfn._xlws.FILTER( DRG_Status!$A$2:$A$100000, (DRG_Status!$F$2:$F$100000=S_Curve_Data!M6) * (DRG_Status!$B$2:$B$100000=S_Curve_Data!$M$1) )),0)/$N$1} -> 0 | T6: =Mappings!B5 -> 45684 | U6: {=IFERROR(ROWS(_xlfn._xlws.FILTER( DRG_Status!$A$2:$A$100000, (DRG_Status!$C$2:$C$100000=S_Curve_Data!T6) * (DRG_Status!$B$2:$B$100000=S_Curve_Data!$T$1) )),0)/$U$1} -> 0 | V6: {=IFERROR(ROWS(_xlfn._xlws.FILTER( DRG_Status!$A$2:$A$100000, (DRG_Status!$D$2:$D$100000=S_Curve_Data!T6) * (DRG_Status!$B$2:$B$100000=S_Curve_Data!$T$1) )),0)/$U$1} -> 0 | W6: {=IFERROR(ROWS(_xlfn._xlws.FILTER( DRG_Status!$A$2:$A$100000, (DRG_Status!$E$2:$E$100000=S_Curve_Data!T6) * (DRG_Status!$B$2:$B$100000=S_Curve_Data!$T$1) )),0)/$U$1} -> 0 | X6: {=IFERROR(ROWS(_xlfn._xlws.FILTER( DRG_Status!$A$2:$A$100000, (DRG_Status!$F$2:$F$100000=S_Curve_Data!T6) * (DRG_Status!$B$2:$B$100000=S_Curve_Data!$T$1) )),0)/$U$1} -> 0 | AA6: 45748 | AB6: {=IFERROR(ROWS(_xlfn._xlws.FILTER( DRG_Status!$A$2:$A$100000, (DRG_Status!$G$2:$G$100000=S_Curve_Data!AA6) * (DRG_Status!$B$2:$B$100000=S_Curve_Data!$AA$1) )),0)/$AB$1} -> 0.027322404 | AC6: {=IFERROR(ROWS(_xlfn._xlws.FILTER( DRG_Status!$A$2:$A$100000, (DRG_Status!$H$2:$H$100000=S_Curve_Data!AA6) * (DRG_Status!$B$2:$B$100000=S_Curve_Data!$AA$1) )),0)/$AB$1} -> 0.10928962 | AD6: {=IFERROR(ROWS(_xlfn._xlws.FILTER( DRG_Status!$A$2:$A$100000, (DRG_Status!$I$2:$I$100000=S_Curve_Data!AA6) * (DRG_Status!$B$2:$B$100000=S_Curve_Data!$AA$1) )),0)/$AB$1} -> 0.13114754 | AE6: {=IFERROR(ROWS(_xlfn._xlws.FILTER( DRG_Status!$A$2:$A$100000, (DRG_Status!$J$2:$J$100000=S_Curve_Data!AA6) * (DRG_Status!$B$2:$B$100000=S_Curve_Data!$AA$1) )),0)/$AB$1} -> 0.016393443 | AH6: 45748 | AI6: {=IFERROR(ROWS(_xlfn._xlws.FILTER( DRG_Status!$A$2:$A$100000, (DRG_Status!$G$2:$G$100000=S_Curve_Data!AH6) * (DRG_Status!$B$2:$B$100000=S_Curve_Data!$AH$1) )),0)/$AI$1} -> 0.11382114 | AJ6: {=IFERROR(ROWS(_xlfn._xlws.FILTER( DRG_Status!$A$2:$A$100000, (DRG_Status!$H$2:$H$100000=S_Curve_Data!AH6) * (DRG_Status!$B$2:$B$100000=S_Curve_Data!$AH$1) )),0)/$AI$1} -> 0.11382114 | AK6: {=IFERROR(ROWS(_xlfn._xlws.FILTER( DRG_Status!$A$2:$A$100000, (DRG_Status!$I$2:$I$100000=S_Curve_Data!AH6) * (DRG_Status!$B$2:$B$100000=S_Curve_Data!$AH$1) )),0)/$AI$1} -> 0 | AL6: {=IFERROR(ROWS(_xlfn._xlws.FILTER( DRG_Status!$A$2:$A$100000, (DRG_Status!$J$2:$J$100000=S_Curve_Data!AH6) * (DRG_Status!$B$2:$B$100000=S_Curve_Data!$AH$1) )),0)/$AI$1} -> 0 | AO6: 45748 | AP6: {=IFERROR(ROWS(_xlfn._xlws.FILTER( DRG_Status!$A$2:$A$100000, (DRG_Status!$G$2:$G$100000=S_Curve_Data!AO6) * (DRG_Status!$B$2:$B$100000=S_Curve_Data!$AO$1) )),0)/$AP$1} -> 0.012711864 | AQ6: {=IFERROR(ROWS(_xlfn._xlws.FILTER( DRG_Status!$A$2:$A$100000, (DRG_Status!$H$2:$H$100000=S_Curve_Data!AO6) * (DRG_Status!$B$2:$B$100000=S_Curve_Data!$AO$1) )),0)/$AP$1} -> 0.14830508 | AR6: {=IFERROR(ROWS(_xlfn._xlws.FILTER( DRG_Status!$A$2:$A$100000, (DRG_Status!$I$2:$I$100000=S_Curve_Data!AO6) * (DRG_Status!$B$2:$B$100000=S_Curve_Data!$AO$1) )),0)/$AP$1} -> 0.19915254 | AS6: {=IFERROR(ROWS(_xlfn._xlws.FILTER( DRG_Status!$A$2:$A$100000, (DRG_Status!$J$2:$J$100000=S_Curve_Data!AO6) * (DRG_Status!$B$2:$B$100000=S_Curve_Data!$AO$1) )),0)/$AP$1} -> 0.042372881
